<?xml version="1.0" encoding="utf-8"?>
<!-- This URDF was automatically created by SolidWorks to URDF Exporter! Originally created by
Stephen Brawner (brawner@gmail.com) 
     Commit Version: 1.6.0-4-g7f85cfe  Build Version: 1.6.7995.38578
     For more information, please see http://wiki.ros.org/sw_urdf_exporter -->
<robot
  name="i1_1030">
  <link
    name="base_link">
    <inertial>
      <origin
        xyz="0.00131644722398935 -0.000608576868207268 0.13738459472279"
        rpy="0 0 0" />
      <mass
        value="4.014226" />
      <inertia
        ixx="0.03979"
        ixy="8.1e-05"
        ixz="-0.00053"
        iyy="0.02642"
        iyz="0.001242"
        izz="0.021602" />
    </inertial>
    <visual>
      <origin
        xyz="0 0 0"
        rpy="0 0 0" />
      <geometry>
        <mesh
          filename="../mjcf_meshes/base_link.STL" />
      </geometry>
      <material
        name="">
        <color
          rgba="0.752941176470588 0.752941176470588 0.752941176470588 1" />
      </material>
    </visual>
    <collision>
      <origin
        xyz="0 0 0"
        rpy="0 0 0" />
      <geometry>
        <mesh
          filename="../mjcf_meshes/base_link.STL" />
      </geometry>
    </collision>
  </link>
  <link
    name="loin_yaw">
    <inertial>
      <origin
        xyz="0.000181135209870565 3.87432271437656E-07 -0.0422741649308185"
        rpy="0 0 0" />
      <mass
        value="1.187105" />
      <inertia
        ixx="0.00213"
        ixy="-0.0"
        ixz="5e-06"
        iyy="0.001181"
        iyz="-0.0"
        izz="0.002038" />
    </inertial>
    <visual>
      <origin
        xyz="0 0 0"
        rpy="0 0 0" />
      <geometry>
        <mesh
          filename="../mjcf_meshes/loin_yaw.STL" />
      </geometry>
      <material
        name="">
        <color
          rgba="0.752941176470588 0.752941176470588 0.752941176470588 1" />
      </material>
    </visual>
    <collision>
      <origin
        xyz="0 0 0"
        rpy="0 0 0" />
      <geometry>
        <mesh
          filename="../mjcf_meshes/loin_yaw.STL" />
      </geometry>
    </collision>
  </link>
  <joint
    name="loin_yaw_joint"
    type="fixed">
    <origin
      xyz="0 0 -0.005"
      rpy="0 0 0" />
    <parent
      link="base_link" />
    <child
      link="loin_yaw" />
    <axis
      xyz="0 0 -1" />
    <limit
      lower="0"
      upper="0"
      effort="0"
      velocity="0" />
  </joint>
  <link
    name="leg_l1">
    <inertial>
      <origin
        xyz="0.00197217477493576 0.0454381096916464 -0.000136900153556372"
        rpy="0 0 0" />
      <mass
        value="0.510247" />
      <inertia
        ixx="0.000292"
        ixy="-2e-06"
        ixz="-1e-06"
        iyy="0.000285"
        iyz="-0.0"
        izz="0.000289" />
    </inertial>
    <visual>
      <origin
        xyz="0 0 0"
        rpy="0 0 0" />
      <geometry>
        <mesh
          filename="../mjcf_meshes/leg_l1.STL" />
      </geometry>
      <material
        name="">
        <color
          rgba="0.752941176470588 0.752941176470588 0.752941176470588 1" />
      </material>
    </visual>
    <collision>
      <origin
        xyz="0 0 0"
        rpy="0 0 0" />
      <geometry>
        <mesh
          filename="../mjcf_meshes/leg_l1.STL" />
      </geometry>
    </collision>
  </link>
  <joint
    name="leg_l1_joint"
    type="revolute">
    <origin
      xyz="0 0.0496 -0.057"
      rpy="0 -0.35 0" />
    <parent
      link="loin_yaw" />
    <child
      link="leg_l1" />
    <axis
      xyz="0 1 0" />
    <limit
      lower="-0.9"
      upper="0.7"
      effort="200"
      velocity="12" />
  </joint>
  <link
    name="leg_l2">
    <inertial>
      <origin
        xyz="-0.029120791545518 1.23457195086718E-05 -0.0358209829806114"
        rpy="0 0 0" />
      <mass
        value="0.095898" />
      <inertia
        ixx="9.9e-05"
        ixy="-0.0"
        ixz="7e-06"
        iyy="0.00016"
        iyz="-0.0"
        izz="0.000121" />
    </inertial>
    <visual>
      <origin
        xyz="0 0 0"
        rpy="0 0 0" />
      <geometry>
        <mesh
          filename="../mjcf_meshes/leg_l2.STL" />
      </geometry>
      <material
        name="">
        <color
          rgba="0.752941176470588 0.752941176470588 0.752941176470588 1" />
      </material>
    </visual>
    <collision>
      <origin
        xyz="0 0 0"
        rpy="0 0 0" />
      <geometry>
        <mesh
          filename="../mjcf_meshes/leg_l2.STL" />
      </geometry>
    </collision>
  </link>
  <joint
    name="leg_l2_joint"
    type="revolute">
    <origin
      xyz="0.0271000000005301 0.0459499999996874 0"
      rpy="0 0 0" />
    <parent
      link="leg_l1" />
    <child
      link="leg_l2" />
    <axis
      xyz="-1 0 0" />
    <limit
      lower="-0.7"
      upper="0.05"
      effort="200"
      velocity="12" />
  </joint>
  <link
    name="leg_l3">
    <inertial>
      <origin
        xyz="-0.00016868208352278 0.0007988022457764 -0.0701262519573794"
        rpy="0 0 0" />
      <mass
        value="0.97356" />
      <inertia
        ixx="0.002505"
        ixy="1e-06"
        ixz="8e-06"
        iyy="0.002491"
        iyz="9.3e-05"
        izz="0.000548" />
    </inertial>
    <visual>
      <origin
        xyz="0 0 0"
        rpy="0 0 0" />
      <geometry>
        <mesh
          filename="../mjcf_meshes/leg_l3.STL" />
      </geometry>
      <material
        name="">
        <color
          rgba="0.752941176470588 0.752941176470588 0.752941176470588 1" />
      </material>
    </visual>
    <collision>
      <origin
        xyz="0 0 0"
        rpy="0 0 0" />
      <geometry>
        <mesh
          filename="../mjcf_meshes/leg_l3.STL" />
      </geometry>
    </collision>
  </link>
  <joint
    name="leg_l3_joint"
    type="revolute">
    <origin
      xyz="-0.0271499999934677 0 -0.0740000000023893"
      rpy="0 0 0" />
    <parent
      link="leg_l2" />
    <child
      link="leg_l3" />
    <axis
      xyz="0 0 -1" />
    <limit
      lower="-0.8"
      upper="0.8"
      effort="200"
      velocity="12" />
  </joint>
  <link
    name="leg_l4">
    <inertial>
      <origin
        xyz="-0.00227702289869041 -0.0277883491198777 -0.0826474860328899"
        rpy="0 0 0" />
      <mass
        value="0.514444" />
      <inertia
        ixx="0.000849"
        ixy="2e-06"
        ixz="-2.9e-05"
        iyy="0.000765"
        iyz="1.1e-05"
        izz="0.000359" />
    </inertial>
    <visual>
      <origin
        xyz="0 0 0"
        rpy="0 0 0" />
      <geometry>
        <mesh
          filename="../mjcf_meshes/leg_l4.STL" />
      </geometry>
      <material
        name="">
        <color
          rgba="0.752941176470588 0.752941176470588 0.752941176470588 1" />
      </material>
    </visual>
    <collision>
      <origin
        xyz="0 0 0"
        rpy="0 0 0" />
      <geometry>
        <mesh
          filename="../mjcf_meshes/leg_l4.STL" />
      </geometry>
    </collision>
  </link>
  <joint
    name="leg_l4_joint"
    type="revolute">
    <origin
      xyz="0 0.0271000000001188 -0.117049999999972"
      rpy="0 0.7 0" />
    <parent
      link="leg_l3" />
    <child
      link="leg_l4" />
    <axis
      xyz="0 1 0" />
    <limit
      lower="-0.1"
      upper="1.8"
      effort="200"
      velocity="12" />
  </joint>
  <link
    name="leg_l5">
    <inertial>
      <origin
        xyz="0.0145628476172153 -0.0199999719918419 -0.0137649111974991"
        rpy="0 0 0" />
      <mass
        value="0.136733" />
      <inertia
        ixx="4.9e-05"
        ixy="-0.0"
        ixz="2.1e-05"
        iyy="0.000298"
        iyz="-0.0"
        izz="0.000318" />
    </inertial>
    <visual>
      <origin
        xyz="0 0 0"
        rpy="0 0 0" />
      <geometry>
        <mesh
          filename="../mjcf_meshes/leg_l5.STL" />
      </geometry>
      <material
        name="">
        <color
          rgba="0.752941176470588 0.752941176470588 0.752941176470588 1" />
      </material>
    </visual>
    <collision>
      <origin
        xyz="0 0 0"
        rpy="0 0 0" />
      <geometry>
        <mesh
          filename="../mjcf_meshes/leg_l5.STL" />
      </geometry>
    </collision>
  </link>
  <joint
    name="leg_l5_joint"
    type="revolute">
    <origin
      xyz="0 -0.0071 -0.2"
      rpy="0 -0.35 0" />
    <parent
      link="leg_l4" />
    <child
      link="leg_l5" />
    <axis
      xyz="0 1 0" />
    <limit
      lower="-0.8"
      upper="0.2"
      effort="200"
      velocity="12" />
  </joint>
  <link
    name="leg_r1">
    <inertial>
      <origin
        xyz="0.00197040790332835 -0.0454678354974241 -0.00014799860932785"
        rpy="0 0 0" />
      <mass
        value="0.510049" />
      <inertia
        ixx="0.000291"
        ixy="2e-06"
        ixz="-1e-06"
        iyy="0.000285"
        iyz="-0.0"
        izz="0.000288" />
    </inertial>
    <visual>
      <origin
        xyz="0 0 0"
        rpy="0 0 0" />
      <geometry>
        <mesh
          filename="../mjcf_meshes/leg_r1.STL" />
      </geometry>
      <material
        name="">
        <color
          rgba="0.752941176470588 0.752941176470588 0.752941176470588 1" />
      </material>
    </visual>
    <collision>
      <origin
        xyz="0 0 0"
        rpy="0 0 0" />
      <geometry>
        <mesh
          filename="../mjcf_meshes/leg_r1.STL" />
      </geometry>
    </collision>
  </link>
  <joint
    name="leg_r1_joint"
    type="revolute">
    <origin
      xyz="0 -0.0495999918226289 -0.0569999999995216"
      rpy="0 -0.35 0" />
    <parent
      link="loin_yaw" />
    <child
      link="leg_r1" />
    <axis
      xyz="0 1 0" />
    <limit
      lower="-0.9"
      upper="0.7"
      effort="200"
      velocity="12" />
  </joint>
  <link
    name="leg_r2">
    <inertial>
      <origin
        xyz="-0.0291207915486844 1.23457195091853E-05 -0.0358237937572448"
        rpy="0 0 0" />
      <mass
        value="0.095898" />
      <inertia
        ixx="9.9e-05"
        ixy="-0.0"
        ixz="7e-06"
        iyy="0.00016"
        iyz="-0.0"
        izz="0.000121" />
    </inertial>
    <visual>
      <origin
        xyz="0 0 0"
        rpy="0 0 0" />
      <geometry>
        <mesh
          filename="../mjcf_meshes/leg_r2.STL" />
      </geometry>
      <material
        name="">
        <color
          rgba="0.752941176470588 0.752941176470588 0.752941176470588 1" />
      </material>
    </visual>
    <collision>
      <origin
        xyz="0 0 0"
        rpy="0 0 0" />
      <geometry>
        <mesh
          filename="../mjcf_meshes/leg_r2.STL" />
      </geometry>
    </collision>
  </link>
  <joint
    name="leg_r2_joint"
    type="revolute">
    <origin
      xyz="0.0270999999994667 -0.0459500000003151 0"
      rpy="0 0 0" />
    <parent
      link="leg_r1" />
    <child
      link="leg_r2" />
    <axis
      xyz="-1 0 0" />
    <limit
      lower="-0.05"
      upper="0.7"
      effort="200"
      velocity="12" />
  </joint>
  <link
    name="leg_r3">
    <inertial>
      <origin
        xyz="0.000284979338666255 -0.000798805705237368 -0.0701269199956975"
        rpy="0 0 0" />
      <mass
        value="0.97356" />
      <inertia
        ixx="0.002505"
        ixy="-1e-06"
        ixz="-4e-06"
        iyy="0.002491"
        iyz="-9.3e-05"
        izz="0.000548" />
    </inertial>
    <visual>
      <origin
        xyz="0 0 0"
        rpy="0 0 0" />
      <geometry>
        <mesh
          filename="../mjcf_meshes/leg_r3.STL" />
      </geometry>
      <material
        name="">
        <color
          rgba="0.752941176470588 0.752941176470588 0.752941176470588 1" />
      </material>
    </visual>
    <collision>
      <origin
        xyz="0 0 0"
        rpy="0 0 0" />
      <geometry>
        <mesh
          filename="../mjcf_meshes/leg_r3.STL" />
      </geometry>
    </collision>
  </link>
  <joint
    name="leg_r3_joint"
    type="revolute">
    <origin
      xyz="-0.0271499999999982 0 -0.0740526859428612"
      rpy="0 0 0" />
    <parent
      link="leg_r2" />
    <child
      link="leg_r3" />
    <axis
      xyz="0 0 -1" />
    <limit
      lower="-0.8" upper="0.8" effort="200" velocity="12" />
  </joint>
  <link
    name="leg_r4">
    <inertial>
      <origin
        xyz="-0.00225013501965593 0.0278368488489967 -0.0826474858542535"
        rpy="0 0 0" />
      <mass
        value="0.514444" />
      <inertia
        ixx="0.000849"
        ixy="-3e-06"
        ixz="-2.9e-05"
        iyy="0.000765"
        iyz="-1.1e-05"
        izz="0.000359" />
    </inertial>
    <visual>
      <origin
        xyz="0 0 0"
        rpy="0 0 0" />
      <geometry>
        <mesh
          filename="../mjcf_meshes/leg_r4.STL" />
      </geometry>
      <material
        name="">
        <color
          rgba="0.752941176470588 0.752941176470588 0.752941176470588 1" />
      </material>
    </visual>
    <collision>
      <origin
        xyz="0 0 0"
        rpy="0 0 0" />
      <geometry>
        <mesh
          filename="../mjcf_meshes/leg_r4.STL" />
      </geometry>
    </collision>
  </link>
  <joint
    name="leg_r4_joint"
    type="revolute">
    <origin
      xyz="0 -0.0270999999988379 -0.117050000000269"
      rpy="0 0.7 0" />
    <parent
      link="leg_r3" />
    <child
      link="leg_r4" />
    <axis
      xyz="0 1 0" />
    <limit
      lower="-0.1" upper="1.8" effort="200" velocity="12" />
  </joint>
  <link
    name="leg_r5">
    <inertial>
      <origin
        xyz="0.0145628476171561 0.0200000280079663 -0.0137649111970828"
        rpy="0 0 0" />
      <mass
        value="0.136733" />
      <inertia
        ixx="4.9e-05"
        ixy="-0.0"
        ixz="2.1e-05"
        iyy="0.000298"
        iyz="-0.0"
        izz="0.000318" />
    </inertial>
    <visual>
      <origin
        xyz="0 0 0"
        rpy="0 0 0" />
      <geometry>
        <mesh
          filename="../mjcf_meshes/leg_r5.STL" />
      </geometry>
      <material
        name="">
        <color
          rgba="0.752941176470588 0.752941176470588 0.752941176470588 1" />
      </material>
    </visual>
    <collision>
      <origin
        xyz="0 0 0"
        rpy="0 0 0" />
      <geometry>
        <mesh
          filename="../mjcf_meshes/leg_r5.STL" />
      </geometry>
    </collision>
  </link>
  <joint
    name="leg_r5_joint"
    type="revolute">
    <origin
      xyz="0 0.00715000000367917 -0.200000000000334"
      rpy="0 -0.35 0" />
    <parent
      link="leg_r4" />
    <child
      link="leg_r5" />
    <axis
      xyz="0 1 0" />
    <limit upper="0.2" effort="200" velocity="12" />
  </joint>
  <link
    name="r_shoulder_pitch">
    <inertial>
      <origin
        xyz="-0.00492132554829663 -0.0442679982867161 -7.250425260652E-05"
        rpy="0 0 0" />
      <mass
        value="0.338408" />
      <inertia
        ixx="0.000162"
        ixy="3e-06"
        ixz="-0.0"
        iyy="0.000132"
        iyz="-0.0"
        izz="0.000153" />
    </inertial>
    <visual>
      <origin
        xyz="0 0 0"
        rpy="0 0 0" />
      <geometry>
        <mesh
          filename="../mjcf_meshes/r_shoulder_pitch.STL" />
      </geometry>
      <material
        name="">
        <color
          rgba="0.752941176470588 0.752941176470588 0.752941176470588 1" />
      </material>
    </visual>
    <collision>
      <origin
        xyz="0 0 0"
        rpy="0 0 0" />
      <geometry>
        <mesh
          filename="../mjcf_meshes/r_shoulder_pitch.STL" />
      </geometry>
    </collision>
  </link>
  <joint
    name="r_shoulder_pitch_joint"
    type="fixed">
    <origin
      xyz="0.00152114352789188 -0.142100042363837 0.19235627367497"
      rpy="0 0 0.0107043277626806" />
    <parent
      link="base_link" />
    <child
      link="r_shoulder_pitch" />
    <axis
      xyz="0 1 0" />
    <limit
      lower="0"
      upper="0"
      effort="0"
      velocity="0" />
  </joint>
  <link
    name="r_shoulder_roll">
    <inertial>
      <origin
        xyz="-0.035711313887014 -0.000382302679649144 -0.0451855112787817"
        rpy="0 0 0" />
      <mass
        value="0.123184" />
      <inertia
        ixx="0.000119"
        ixy="-0.0"
        ixz="1.2e-05"
        iyy="0.000138"
        iyz="-0.0"
        izz="0.000114" />
    </inertial>
    <visual>
      <origin
        xyz="0 0 0"
        rpy="0 0 0" />
      <geometry>
        <mesh
          filename="../mjcf_meshes/r_shoulder_roll.STL" />
      </geometry>
      <material
        name="">
        <color
          rgba="0.752941176470588 0.752941176470588 0.752941176470588 1" />
      </material>
    </visual>
    <collision>
      <origin
        xyz="0 0 0"
        rpy="0 0 0" />
      <geometry>
        <mesh
          filename="../mjcf_meshes/r_shoulder_roll.STL" />
      </geometry>
    </collision>
  </link>
  <joint
    name="r_shoulder_roll_joint"
    type="fixed">
    <origin
      xyz="0.0294988163604422 -0.0489500000001077 0.000264259939019407"
      rpy="0 0 -0.0107043277626806" />
    <parent
      link="r_shoulder_pitch" />
    <child
      link="r_shoulder_roll" />
    <axis
      xyz="0.999902588164708 0.010703693844858 0.00895796403171279" />
    <limit
      lower="0"
      upper="0"
      effort="0"
      velocity="0" />
  </joint>
  <link
    name="r_shoulder_yaw">
    <inertial>
      <origin
        xyz="0.000629657295944031 0.000347118794732038 -0.0606678838887164"
        rpy="0 0 0" />
      <mass
        value="0.50875" />
      <inertia
        ixx="0.000985"
        ixy="-0.0"
        ixz="6e-06"
        iyy="0.001007"
        iyz="2.2e-05"
        izz="0.000261" />
    </inertial>
    <visual>
      <origin
        xyz="0 0 0"
        rpy="0 0 0" />
      <geometry>
        <mesh
          filename="../mjcf_meshes/r_shoulder_yaw.STL" />
      </geometry>
      <material
        name="">
        <color
          rgba="0.752941176470588 0.752941176470588 0.752941176470588 1" />
      </material>
    </visual>
    <collision>
      <origin
        xyz="0 0 0"
        rpy="0 0 0" />
      <geometry>
        <mesh
          filename="../mjcf_meshes/r_shoulder_yaw.STL" />
      </geometry>
    </collision>
  </link>
  <joint
    name="r_shoulder_yaw_joint"
    type="fixed">
    <origin
      xyz="-0.0332572504317691 -0.000356010107427529 -0.0828512585933959"
      rpy="0 0 0" />
    <parent
      link="r_shoulder_roll" />
    <child
      link="r_shoulder_yaw" />
    <axis
      xyz="0.0290244273796275 0.000310698861993819 0.999578654274641" />
    <limit
      lower="0"
      upper="0"
      effort="0"
      velocity="0" />
  </joint>
  <link
    name="r_arm_pitch">
    <inertial>
      <origin
        xyz="0.00451884090359277 0.019059781533003 -0.115014176941201"
        rpy="0 0 0" />
      <mass
        value="0.347006" />
      <inertia
        ixx="0.000986"
        ixy="0.000001"
        ixz="0.000053"
        iyy="0.001003"
        iyz="0.000072"
        izz="0.000228" />
    </inertial>
    <visual>
      <origin
        xyz="0 0 0"
        rpy="0 0 0" />
      <geometry>
        <mesh
          filename="../mjcf_meshes/r_arm_pitch.STL" />
      </geometry>
      <material
        name="">
        <color
          rgba="0.752941176470588 0.752941176470588 0.752941176470588 1" />
      </material>
    </visual>
    <collision>
      <origin
        xyz="0 0 0"
        rpy="0 0 0" />
      <geometry>
        <mesh
          filename="../mjcf_meshes/r_arm_pitch.STL" />
      </geometry>
    </collision>
  </link>
  <joint
    name="r_arm_pitch_joint"
    type="fixed">
    <origin
      xyz="0.00108857599788274 -0.0155142365719634 -0.102970782946762"
      rpy="0 0 0" />
    <parent
      link="r_shoulder_yaw" />
    <child
      link="r_arm_pitch" />
    <axis
      xyz="0.010704123340247 -0.999942709230642 0" />
    <limit
      lower="0"
      upper="0"
      effort="0"
      velocity="0" />
  </joint>
  <link
    name="l_shoulder_pitch">
    <inertial>
      <origin
        xyz="-0.00539414955285367 0.044212802652057 0.00011446840195084"
        rpy="0 0 0" />
      <mass
        value="0.338408" />
      <inertia
        ixx="0.000163"
        ixy="-2e-06"
        ixz="-0.0"
        iyy="0.000132"
        iyz="-0.0"
        izz="0.000153" />
    </inertial>
    <visual>
      <origin
        xyz="0 0 0"
        rpy="0 0 0" />
      <geometry>
        <mesh
          filename="../mjcf_meshes/l_shoulder_pitch.STL" />
      </geometry>
      <material
        name="">
        <color
          rgba="0.752941176470588 0.752941176470588 0.752941176470588 1" />
      </material>
    </visual>
    <collision>
      <origin
        xyz="0 0 0"
        rpy="0 0 0" />
      <geometry>
        <mesh
          filename="../mjcf_meshes/l_shoulder_pitch.STL" />
      </geometry>
    </collision>
  </link>
  <joint
    name="l_shoulder_pitch_joint"
    type="fixed">
    <origin
      xyz="-0.00152114352789363 0.142100042367547 0.192356273672232"
      rpy="0 0 0" />
    <parent
      link="base_link" />
    <child
      link="l_shoulder_pitch" />
    <axis
      xyz="-0.0107041233402471 0.999942709230642 0" />
    <limit
      lower="0"
      upper="0"
      effort="0"
      velocity="0" />
  </joint>
  <link
    name="l_shoulder_roll">
    <inertial>
      <origin
        xyz="-0.0374016397167701 -0.000400308633556334 -0.0437967567706124"
        rpy="0 0 0" />
      <mass
        value="0.123182" />
      <inertia
        ixx="0.00012"
        ixy="-0.0"
        ixz="1.2e-05"
        iyy="0.000138"
        iyz="-0.0"
        izz="0.000113" />
    </inertial>
    <visual>
      <origin
        xyz="0 0 0"
        rpy="0 0 0" />
      <geometry>
        <mesh
          filename="../mjcf_meshes/l_shoulder_roll.STL" />
      </geometry>
      <material
        name="">
        <color
          rgba="0.752941176470588 0.752941176470588 0.752941176470588 1" />
      </material>
    </visual>
    <collision>
      <origin
        xyz="0 0 0"
        rpy="0 0 0" />
      <geometry>
        <mesh
          filename="../mjcf_meshes/l_shoulder_roll.STL" />
      </geometry>
    </collision>
  </link>
  <joint
    name="l_shoulder_roll_joint"
    type="fixed">
    <origin
      xyz="0.028961914097807 0.0492628342080569 -0.000856269663819131"
      rpy="0 0 0" />
    <parent
      link="l_shoulder_pitch" />
    <child
      link="l_shoulder_roll" />
    <axis
      xyz="-0.999521387644461 -0.0106996131992724 0.0290260903098726" />
    <limit
      lower="0"
      upper="0"
      effort="0"
      velocity="0" />
  </joint>
  <link
    name="l_shoulder_yaw">
    <inertial>
      <origin
        xyz="-0.00164610759854025 -0.000353668339429902 -0.0606398659511323"
        rpy="0 0 0" />
      <mass
        value="0.509094" />
      <inertia
        ixx="0.000984"
        ixy="-1e-06"
        ixz="-2.1e-05"
        iyy="0.001007"
        iyz="-2.2e-05"
        izz="0.000262" />
    </inertial>
    <visual>
      <origin
        xyz="0 0 0"
        rpy="0 0 0" />
      <geometry>
        <mesh
          filename="../mjcf_meshes/l_shoulder_yaw.STL" />
      </geometry>
      <material
        name="">
        <color
          rgba="0.752941176470588 0.752941176470588 0.752941176470588 1" />
      </material>
    </visual>
    <collision>
      <origin
        xyz="0 0 0"
        rpy="0 0 0" />
      <geometry>
        <mesh
          filename="../mjcf_meshes/l_shoulder_yaw.STL" />
      </geometry>
    </collision>
  </link>
  <joint
    name="l_shoulder_yaw_joint"
    type="fixed">
    <origin
      xyz="-0.0363796936599959 -0.000389435038538916 -0.0815283308399195"
      rpy="0 0 0" />
    <parent
      link="l_shoulder_roll" />
    <child
      link="l_shoulder_yaw" />
    <axis
      xyz="0.0290244273796269 0.000310698860122039 0.999578654274641" />
    <limit
      lower="0"
      upper="0"
      effort="0"
      velocity="0" />
  </joint>
  <link
    name="l_arm_pitch">
    <inertial>
      <origin
        xyz="0.00495626676851831 -0.0189667407838877 -0.115014027269049"
        rpy="0 0 0" />
      <mass
        value="0.347001456199068" />
      <inertia
        ixx="0.000986"
        ixy="-0.000001"
        ixz="-0.000054"
        iyy="0.001003"
        iyz="-0.000071"
        izz="0.000228" />
    </inertial>
    <visual>
      <origin
        xyz="0 0 0"
        rpy="0 0 0" />
      <geometry>
        <mesh
          filename="../mjcf_meshes/l_arm_pitch.STL" />
      </geometry>
      <material
        name="">
        <color
          rgba="0.752941176470588 0.752941176470588 0.752941176470588 1" />
      </material>
    </visual>
    <collision>
      <origin
        xyz="0 0 0"
        rpy="0 0 0" />
      <geometry>
        <mesh
          filename="../mjcf_meshes/l_arm_pitch.STL" />
      </geometry>
    </collision>
  </link>
  <joint
    name="l_arm_pitch_joint"
    type="fixed">
    <origin
      xyz="-0.00315495415371205 0.0154921165359136 -0.10293149731973"
      rpy="0 0 0" />
    <parent
      link="l_shoulder_yaw" />
    <child
      link="l_arm_pitch" />
    <axis
      xyz="0.010704123340247 -0.999942709230642 0" />
    <limit
      lower="0"
      upper="0"
      effort="0"
      velocity="0" />
  </joint>
  <link
    name="head">
    <inertial>
      <origin
        xyz="-0.00836766593099098 -0.00132146787410694 0.320764300085037"
        rpy="0 0 0" />
      <mass
        value="0.328819" />
      <inertia
        ixx="0.000736"
        ixy="0.000002"
        ixz="0.000098"
        iyy="0.000767"
        iyz="0.000008"
        izz="0.000240" />
    </inertial>
    <visual>
      <origin
        xyz="0 0 0"
        rpy="0 0 0" />
      <geometry>
        <mesh
          filename="../mjcf_meshes/head.STL" />
      </geometry>
      <material
        name="">
        <color
          rgba="0.752941176470588 0.752941176470588 0.752941176470588 1" />
      </material>
    </visual>
    <collision>
      <origin
        xyz="0 0 0"
        rpy="0 0 0" />
      <geometry>
        <mesh
          filename="../mjcf_meshes/head.STL" />
      </geometry>
    </collision>
  </link>
  <joint
    name="head_joint"
    type="fixed">
    <origin
      xyz="0 0 0"
      rpy="0 0 0" />
    <parent
      link="base_link" />
    <child
      link="head" />
    <axis
      xyz="0 0 0" />
  </joint>
  <link
    name="imu">
    <inertial>
      <origin
        xyz="2.14583463458172E-18 -1.73472347597681E-18 -0.00450000000000006"
        rpy="0 0 0" />
      <mass
        value="0.00842400000000001" />
      <inertia
        ixx="9.66654000000001E-07"
        ixy="8.60267837055149E-23"
        ixz="4.07980620583451E-23"
        iyy="5.31414000000001E-07"
        iyz="-7.31396595201204E-23"
        izz="1.384344E-06" />
    </inertial>
    <visual>
      <origin
        xyz="0 0 0"
        rpy="0 0 0" />
      <geometry>
        <mesh
          filename="../mjcf_meshes/imu.STL" />
      </geometry>
      <material
        name="">
        <color
          rgba="0.0627450980392157 0.517647058823529 1 1" />
      </material>
    </visual>
    <collision>
      <origin
        xyz="0 0 0"
        rpy="0 0 0" />
      <geometry>
        <mesh
          filename="../mjcf_meshes/imu.STL" />
      </geometry>
    </collision>
  </link>
  <joint
    name="imu_joint"
    type="fixed">
    <origin
      xyz="-3.7464E-05 0.0034998 0.26922"
      rpy="0 0 0.010704" />
    <parent
      link="base_link" />
    <child
      link="imu" />
    <axis
      xyz="0 0 0" />
  </joint>
</robot>