<?xml version='1.0' encoding='utf-8'?>
<robot name="i1_1028">
  <link name="base_link">
    <inertial>
      <origin xyz="0.00131644722398935 -0.000608576868207266 0.137384594722791" rpy="0 0 0" />
      <mass value="3.5999235547977" />
      <inertia ixx="0.0125608170063445" ixy="8.60874648979012E-05" ixz="-8.41983711144011E-06"
        iyy="0.00529403107927784" iyz="5.03618691983168E-05" izz="0.0091787118908814" />
    </inertial>
    <visual>
      <origin xyz="0 0 0" rpy="0 0 0" />
      <geometry>
        <mesh filename="/data/wanshan/Desktop/robotics/Assets/URDF/i1/meshes/base_link.STL" />
      </geometry>
      <material name="">
        <color rgba="0.752941176470588 0.752941176470588 0.752941176470588 1" />
      </material>
    </visual>
    <collision>
      <origin xyz="0 0 0" rpy="0 0 0" />
      <geometry>
        <mesh filename="/data/wanshan/Desktop/robotics/Assets/URDF/i1/meshes/base_link.STL" />
      </geometry>
    </collision>
  </link>
  <link name="loin_yaw">
    <inertial>
      <origin xyz="0.0 -0.000126 0.008359" rpy="0 0 0" />
      <mass value="1.187105" />
      <inertia ixx="0.001181" ixy="-0.0" ixz="-0.0" iyy="0.00213" iyz="-5e-06" izz="0.002038" />
    </inertial>
    <visual>
      <origin xyz="0 0 0" rpy="0 0 0" />
      <geometry>
        <mesh filename="/data/wanshan/Desktop/robotics/Assets/URDF/i1/meshes/loin_yaw.STL" />
      </geometry>
      <material name="">
        <color rgba="0.752941176470588 0.752941176470588 0.752941176470588 1" />
      </material>
    </visual>
    <collision>
      <origin xyz="0 0 0" rpy="0 0 0" />
      <geometry>
        <mesh filename="/data/wanshan/Desktop/robotics/Assets/URDF/i1/meshes/loin_yaw.STL" />
      </geometry>
    </collision>
  </link>
  <joint name="torso_joint" type="revolute">
    <origin xyz="0 0 -0.005" rpy="0 0 0" />
    <parent link="base_link" />
    <child link="loin_yaw" />
    <axis xyz="0 0 -1" />
    <limit lower="0" upper="0" effort="0" velocity="0" />
  </joint>
  <link name="leg_l1">
    <inertial>
      <origin xyz="0.095268 -0.004066 -6.7e-05" rpy="0 0 0" />
      <mass value="0.510247" />
      <inertia ixx="0.000285" ixy="2e-06" ixz="-0.0" iyy="0.000292" iyz="1e-06" izz="0.000289" />
    </inertial>
    <visual>
      <origin xyz="0 0 0" rpy="0 0 0" />
      <geometry>
        <mesh filename="/data/wanshan/Desktop/robotics/Assets/URDF/i1/meshes/leg_l1.STL" />
      </geometry>
      <material name="">
        <color rgba="0.752941176470588 0.752941176470588 0.752941176470588 1" />
      </material>
    </visual>
    <collision>
      <origin xyz="0 0 0" rpy="0 0 0" />
      <geometry>
        <mesh filename="/data/wanshan/Desktop/robotics/Assets/URDF/i1/meshes/leg_l1.STL" />
      </geometry>
    </collision>
  </link>
  <joint name="left_hip_pitch_joint" type="revolute">
    <origin xyz="0 0.0496000081773711 -0.0570000000004782" rpy="0 -0.35 0" />
    <parent link="loin_yaw" />
    <child link="leg_l1" />
    <axis xyz="0 1 0" />
    <limit lower="-0.9" upper="0.7" effort="200" velocity="12" />
  </joint>
  <link name="leg_l2">
    <inertial>
      <origin xyz="0.095562 0.00202 -0.03582" rpy="0 0 0" />
      <mass value="0.095898" />
      <inertia ixx="0.00016" ixy="-0.0" ixz="-0.0" iyy="9.9e-05" iyz="-7e-06" izz="0.000121" />
    </inertial>
    <visual>
      <origin xyz="0 0 0" rpy="0 0 0" />
      <geometry>
        <mesh filename="/data/wanshan/Desktop/robotics/Assets/URDF/i1/meshes/leg_l2.STL" />
      </geometry>
      <material name="">
        <color rgba="0.752941176470588 0.752941176470588 0.752941176470588 1" />
      </material>
    </visual>
    <collision>
      <origin xyz="0 0 0" rpy="0 0 0" />
      <geometry>
        <mesh filename="/data/wanshan/Desktop/robotics/Assets/URDF/i1/meshes/leg_l2.STL" />
      </geometry>
    </collision>
  </link>
  <joint name="left_hip_roll_joint" type="revolute">
    <origin xyz="0.0271000000005301 0.0459499999996874 0" rpy="0 0 0" />
    <parent link="leg_l1" />
    <child link="leg_l2" />
    <axis xyz="-1 0 0" />
    <limit lower="-0.7" upper="0.05" effort="200" velocity="12" />
  </joint>
  <link name="leg_l3">
    <inertial>
      <origin xyz="0.097531 0.000116 -0.144577" rpy="0 0 0" />
      <mass value="0.97356" />
      <inertia ixx="0.002491" ixy="-1e-06" ixz="9.3e-05" iyy="0.002505" iyz="-8e-06" izz="0.000548" />
    </inertial>
    <visual>
      <origin xyz="0 0 0" rpy="0 0 0" />
      <geometry>
        <mesh filename="/data/wanshan/Desktop/robotics/Assets/URDF/i1/meshes/leg_l3.STL" />
      </geometry>
      <material name="">
        <color rgba="0.752941176470588 0.752941176470588 0.752941176470588 1" />
      </material>
    </visual>
    <collision>
      <origin xyz="0 0 0" rpy="0 0 0" />
      <geometry>
        <mesh filename="/data/wanshan/Desktop/robotics/Assets/URDF/i1/meshes/leg_l3.STL" />
      </geometry>
    </collision>
  </link>
  <joint name="left_hip_yaw_joint" type="revolute">
    <origin xyz="-0.0271499999934677 0 -0.0740000000023893" rpy="0 0 0" />
    <parent link="leg_l2" />
    <child link="leg_l3" />
    <axis xyz="0 0 -1" />
    <limit lower="-0.8" upper="0.8" effort="200" velocity="12" />
  </joint>
  <link name="leg_l4">
    <inertial>
      <origin xyz="0.092903 0.001218 -0.272377" rpy="0 0 0" />
      <mass value="0.514444" />
      <inertia ixx="0.000765" ixy="-2e-06" ixz="1.1e-05" iyy="0.000849" iyz="2.9e-05" izz="0.000359" />
    </inertial>
    <visual>
      <origin xyz="0 0 0" rpy="0 0 0" />
      <geometry>
        <mesh filename="/data/wanshan/Desktop/robotics/Assets/URDF/i1/meshes/leg_l4.STL" />
      </geometry>
      <material name="">
        <color rgba="0.752941176470588 0.752941176470588 0.752941176470588 1" />
      </material>
    </visual>
    <collision>
      <origin xyz="0 0 0" rpy="0 0 0" />
      <geometry>
        <mesh filename="/data/wanshan/Desktop/robotics/Assets/URDF/i1/meshes/leg_l4.STL" />
      </geometry>
    </collision>
  </link>
  <joint name="left_knee_joint" type="revolute">
    <origin xyz="0 0.0271000000001188 -0.117049999999972" rpy="0 0.7 0" />
    <parent link="leg_l3" />
    <child link="leg_l4" />
    <axis xyz="0 1 0" />
    <limit lower="-0.1" upper="1.8" effort="200" velocity="12" />
  </joint>
  <link name="leg_l5">
    <inertial>
      <origin xyz="0.09555 -0.014513 -0.404815" rpy="0 0 0" />
      <mass value="0.136733" />
      <inertia ixx="0.000298" ixy="-0.0" ixz="-0.0" iyy="4.9e-05" iyz="-2.1e-05" izz="0.000318" />
    </inertial>
    <visual>
      <origin xyz="0 0 0" rpy="0 0 0" />
      <geometry>
        <mesh filename="/data/wanshan/Desktop/robotics/Assets/URDF/i1/meshes/leg_l5.STL" />
      </geometry>
      <material name="">
        <color rgba="0.752941176470588 0.752941176470588 0.752941176470588 1" />
      </material>
    </visual>
    <collision>
      <origin xyz="0 0 0" rpy="0 0 0" />
      <geometry>
        <mesh filename="/data/wanshan/Desktop/robotics/Assets/URDF/i1/meshes/leg_l5.STL" />
      </geometry>
    </collision>
  </link>
  <joint name="left_ankle_joint" type="revolute">
    <origin xyz="0 -0.00709999999740331 -0.200000000000092" rpy="0 -0.35 0" />
    <parent link="leg_l4" />
    <child link="leg_l5" />
    <axis xyz="0 1 0" />
    <limit lower="-0.8" upper="0.2" effort="200" velocity="12" />
  </joint>
  <link name="leg_r1">
    <inertial>
      <origin xyz="-0.095283 -0.004066 -7.4e-05" rpy="0 0 0" />
      <mass value="0.510049" />
      <inertia ixx="0.000285" ixy="-2e-06" ixz="-0.0" iyy="0.000291" iyz="1e-06" izz="0.000288" />
    </inertial>
    <visual>
      <origin xyz="0 0 0" rpy="0 0 0" />
      <geometry>
        <mesh filename="/data/wanshan/Desktop/robotics/Assets/URDF/i1/meshes/leg_r1.STL" />
      </geometry>
      <material name="">
        <color rgba="0.752941176470588 0.752941176470588 0.752941176470588 1" />
      </material>
    </visual>
    <collision>
      <origin xyz="0 0 0" rpy="0 0 0" />
      <geometry>
        <mesh filename="/data/wanshan/Desktop/robotics/Assets/URDF/i1/meshes/leg_r1.STL" />
      </geometry>
    </collision>
  </link>
  <joint name="right_hip_pitch_joint" type="revolute">
    <origin xyz="0 -0.0495999918226289 -0.0569999999995216" rpy="0 -0.35 0" />
    <parent link="loin_yaw" />
    <child link="leg_r1" />
    <axis xyz="0 1 0" />
    <limit lower="-0.9" upper="0.7" effort="200" velocity="12" />
  </joint>
  <link name="leg_r2">
    <inertial>
      <origin xyz="-0.095538 0.00202 -0.035822" rpy="0 0 0" />
      <mass value="0.095898" />
      <inertia ixx="0.00016" ixy="-0.0" ixz="-0.0" iyy="9.9e-05" iyz="-7e-06" izz="0.000121" />
    </inertial>
    <visual>
      <origin xyz="0 0 0" rpy="0 0 0" />
      <geometry>
        <mesh filename="/data/wanshan/Desktop/robotics/Assets/URDF/i1/meshes/leg_r2.STL" />
      </geometry>
      <material name="">
        <color rgba="0.752941176470588 0.752941176470588 0.752941176470588 1" />
      </material>
    </visual>
    <collision>
      <origin xyz="0 0 0" rpy="0 0 0" />
      <geometry>
        <mesh filename="/data/wanshan/Desktop/robotics/Assets/URDF/i1/meshes/leg_r2.STL" />
      </geometry>
    </collision>
  </link>
  <joint name="right_hip_roll_joint" type="revolute">
    <origin xyz="0.0270999999994667 -0.0459500000003151 0" rpy="0 0 0" />
    <parent link="leg_r1" />
    <child link="leg_r2" />
    <axis xyz="-1 0 0" />
    <limit lower="-0.05" upper="0.7" effort="200" velocity="12" />
  </joint>
  <link name="leg_r3">
    <inertial>
      <origin xyz="-0.097531 -9.9e-05 -0.144631" rpy="0 0 0" />
      <mass value="0.97356" />
      <inertia ixx="0.002491" ixy="1e-06" ixz="-9.3e-05" iyy="0.002505" iyz="4e-06" izz="0.000548" />
    </inertial>
    <visual>
      <origin xyz="0 0 0" rpy="0 0 0" />
      <geometry>
        <mesh filename="/data/wanshan/Desktop/robotics/Assets/URDF/i1/meshes/leg_r3.STL" />
      </geometry>
      <material name="">
        <color rgba="0.752941176470588 0.752941176470588 0.752941176470588 1" />
      </material>
    </visual>
    <collision>
      <origin xyz="0 0 0" rpy="0 0 0" />
      <geometry>
        <mesh filename="/data/wanshan/Desktop/robotics/Assets/URDF/i1/meshes/leg_r3.STL" />
      </geometry>
    </collision>
  </link>
  <joint name="right_hip_yaw_joint" type="revolute">
    <origin xyz="-0.0271499999999982 0 -0.0740526859428612" rpy="0 0 0" />
    <parent link="leg_r2" />
    <child link="leg_r3" />
    <axis xyz="0 0 -1" />
    <limit lower="-0.8" upper="0.8" effort="200" velocity="12" />
  </joint>
  <link name="leg_r4">
    <inertial>
      <origin xyz="-0.092854 0.001151 -0.27243" rpy="0 0 0" />
      <mass value="0.514444" />
      <inertia ixx="0.000765" ixy="3e-06" ixz="-1.1e-05" iyy="0.000849" iyz="2.9e-05" izz="0.000359" />
    </inertial>
    <visual>
      <origin xyz="0 0 0" rpy="0 0 0" />
      <geometry>
        <mesh filename="/data/wanshan/Desktop/robotics/Assets/URDF/i1/meshes/leg_r4.STL" />
      </geometry>
      <material name="">
        <color rgba="0.752941176470588 0.752941176470588 0.752941176470588 1" />
      </material>
    </visual>
    <collision>
      <origin xyz="0 0 0" rpy="0 0 0" />
      <geometry>
        <mesh filename="/data/wanshan/Desktop/robotics/Assets/URDF/i1/meshes/leg_r4.STL" />
      </geometry>
    </collision>
  </link>
  <joint name="right_knee_joint" type="revolute">
    <origin xyz="0 -0.0270999999988379 -0.117050000000269" rpy="0 0.7 0" />
    <parent link="leg_r3" />
    <child link="leg_r4" />
    <axis xyz="0 1 0" />
    <limit lower="-0.1" upper="1.8" effort="200" velocity="12" />
  </joint>
  <link name="leg_r5">
    <inertial>
      <origin xyz="-0.0955 -0.014513 -0.404868" rpy="0 0 0" />
      <mass value="0.136733" />
      <inertia ixx="0.000298" ixy="-0.0" ixz="-0.0" iyy="4.9e-05" iyz="-2.1e-05" izz="0.000318" />
    </inertial>
    <visual>
      <origin xyz="0 0 0" rpy="0 0 0" />
      <geometry>
        <mesh filename="/data/wanshan/Desktop/robotics/Assets/URDF/i1/meshes/leg_r5.STL" />
      </geometry>
      <material name="">
        <color rgba="0.752941176470588 0.752941176470588 0.752941176470588 1" />
      </material>
    </visual>
    <collision>
      <origin xyz="0 0 0" rpy="0 0 0" />
      <geometry>
        <mesh filename="/data/wanshan/Desktop/robotics/Assets/URDF/i1/meshes/leg_r5.STL" />
      </geometry>
    </collision>
  </link>
  <joint name="right_ankle_joint" type="revolute">
    <origin xyz="0 0.00715000000367917 -0.200000000000334" rpy="0 -0.35 0" />
    <parent link="leg_r4" />
    <child link="leg_r5" />
    <axis xyz="0 1 0" />
    <limit lower="-0.9" upper="0.2" effort="200" velocity="12" />
  </joint>
  <link name="r_shoulder_pitch">
    <inertial>
      <origin xyz="-0.189099 0.002136 0.254284" rpy="0 0 0" />
      <mass value="0.338408" />
      <inertia ixx="0.000132" ixy="-3e-06" ixz="-0.0" iyy="0.000162" iyz="-0.0" izz="0.000153" />
    </inertial>
    <visual>
      <origin xyz="0 0 0" rpy="0 0 0" />
      <geometry>
        <mesh filename="/data/wanshan/Desktop/robotics/Assets/URDF/i1/meshes/r_shoulder_pitch.STL" />
      </geometry>
      <material name="">
        <color rgba="0.752941176470588 0.752941176470588 0.752941176470588 1" />
      </material>
    </visual>
    <collision>
      <origin xyz="0 0 0" rpy="0 0 0" />
      <geometry>
        <mesh filename="/data/wanshan/Desktop/robotics/Assets/URDF/i1/meshes/r_shoulder_pitch.STL" />
      </geometry>
    </collision>
  </link>
  <joint name="r_shoulder_pitch_joint" type="revolute">
    <origin xyz="0.00152114352789188 -0.142100042363837 0.19235627367497"
      rpy="0 -0.2 0" />
    <parent link="base_link" />
    <child link="r_shoulder_pitch" />
    <axis xyz="0 1 0" />
    <limit lower="0" upper="0" effort="0" velocity="0" />
  </joint>
  <link name="r_shoulder_roll">
    <inertial>
      <origin xyz="-0.191114 0.004168 0.209436" rpy="0 0 0" />
      <mass value="0.123184" />
      <inertia ixx="0.000138" ixy="-0.0" ixz="-0.0" iyy="0.000119" iyz="-1.2e-05" izz="0.000114" />
    </inertial>
    <visual>
      <origin xyz="0 0 0" rpy="0 0 0" />
      <geometry>
        <mesh filename="/data/wanshan/Desktop/robotics/Assets/URDF/i1/meshes/r_shoulder_roll.STL" />
      </geometry>
      <material name="">
        <color rgba="0.752941176470588 0.752941176470588 0.752941176470588 1" />
      </material>
    </visual>
    <collision>
      <origin xyz="0 0 0" rpy="0 0 0" />
      <geometry>
        <mesh filename="/data/wanshan/Desktop/robotics/Assets/URDF/i1/meshes/r_shoulder_roll.STL" />
      </geometry>
    </collision>
  </link>
  <joint name="r_shoulder_roll_joint" type="revolute">
    <origin xyz="0.0294988163604422 -0.0489500000001077 0.000264259939019407"
      rpy="0 0 -0.0107043277626806" />
    <parent link="r_shoulder_pitch" />
    <child link="r_shoulder_roll" />
    <axis xyz="0.999902588164708 0.010703693844858 0.00895796403171279" />
    <limit lower="0" upper="0" effort="0" velocity="0" />
  </joint>
  <link name="r_shoulder_yaw">
    <inertial>
      <origin xyz="-0.190025 0.001119 0.111343" rpy="0 0 0" />
      <mass value="0.50875" />
      <inertia ixx="0.001007" ixy="-0.0" ixz="2.2e-05" iyy="0.000985" iyz="-6e-06" izz="0.000261" />
    </inertial>
    <visual>
      <origin xyz="0 0 0" rpy="0 0 0" />
      <geometry>
        <mesh filename="/data/wanshan/Desktop/robotics/Assets/URDF/i1/meshes/r_shoulder_yaw.STL" />
      </geometry>
      <material name="">
        <color rgba="0.752941176470588 0.752941176470588 0.752941176470588 1" />
      </material>
    </visual>
    <collision>
      <origin xyz="0 0 0" rpy="0 0 0" />
      <geometry>
        <mesh filename="/data/wanshan/Desktop/robotics/Assets/URDF/i1/meshes/r_shoulder_yaw.STL" />
      </geometry>
    </collision>
  </link>
  <joint name="r_shoulder_yaw_joint" type="revolute">
    <origin xyz="-0.0332572504317691 -0.000356010107427529 -0.0828512585933959" rpy="0 0 0" />
    <parent link="r_shoulder_roll" />
    <child link="r_shoulder_yaw" />
    <axis xyz="0.0290244273796275 0.000310698861993819 0.999578654274641" />
    <limit lower="0" upper="0" effort="0" velocity="0" />
  </joint>
  <link name="r_arm_pitch">
    <inertial>
      <origin xyz="-0.187541 -0.003892 -0.046217" rpy="0 0 0" />
      <mass value="0.347026" />
      <inertia ixx="0.001003" ixy="-1e-06" ixz="7.2e-05" iyy="0.000986" iyz="-5.3e-05"
        izz="0.000228" />
    </inertial>
    <visual>
      <origin xyz="0 0 0" rpy="0 0 0" />
      <geometry>
        <mesh filename="/data/wanshan/Desktop/robotics/Assets/URDF/i1/meshes/r_arm_pitch.STL" />
      </geometry>
      <material name="">
        <color rgba="0.752941176470588 0.752941176470588 0.752941176470588 1" />
      </material>
    </visual>
    <collision>
      <origin xyz="0 0 0" rpy="0 0 0" />
      <geometry>
        <mesh filename="/data/wanshan/Desktop/robotics/Assets/URDF/i1/meshes/r_arm_pitch.STL" />
      </geometry>
    </collision>
  </link>
  <joint name="r_elbow_joint" type="revolute">
    <origin xyz="0.00108857599788274 -0.0155142365719634 -0.102970782946762" rpy="0 0 0" />
    <parent link="r_shoulder_yaw" />
    <child link="r_arm_pitch" />
    <axis xyz="0.010704123340247 -0.999942709230642 0" />
    <limit lower="0" upper="0" effort="0" velocity="0" />
  </joint>
  <link name="l_shoulder_pitch">
    <inertial>
      <origin xyz="0.18901 0.006184 0.254442" rpy="0 0 0" />
      <mass value="0.338408" />
      <inertia ixx="0.000132" ixy="2e-06" ixz="-0.0" iyy="0.000163" iyz="-0.0" izz="0.000153" />
    </inertial>
    <visual>
      <origin xyz="0 0 0" rpy="0 0 0" />
      <geometry>
        <mesh filename="/data/wanshan/Desktop/robotics/Assets/URDF/i1/meshes/l_shoulder_pitch.STL" />
      </geometry>
      <material name="">
        <color rgba="0.752941176470588 0.752941176470588 0.752941176470588 1" />
      </material>
    </visual>
    <collision>
      <origin xyz="0 0 0" rpy="0 0 0" />
      <geometry>
        <mesh filename="/data/wanshan/Desktop/robotics/Assets/URDF/i1/meshes/l_shoulder_pitch.STL" />
      </geometry>
    </collision>
  </link>
  <joint name="l_shoulder_pitch_joint" type="revolute">
    <origin xyz="-0.00152114352789363 0.142100042367547 0.192356273672232" rpy="0 -0.2 0" />
    <parent link="base_link" />
    <child link="l_shoulder_pitch" />
    <axis xyz="-0.0107041233402471 0.999942709230642 0" />
    <limit lower="0" upper="0" effort="0" velocity="0" />
  </joint>
  <link name="l_shoulder_roll">
    <inertial>
      <origin xyz="0.190962 0.00996 0.209704" rpy="0 0 0" />
      <mass value="0.123182" />
      <inertia ixx="0.000138" ixy="-0.0" ixz="-0.0" iyy="0.00012" iyz="-1.2e-05" izz="0.000113" />
    </inertial>
    <visual>
      <origin xyz="0 0 0" rpy="0 0 0" />
      <geometry>
        <mesh filename="/data/wanshan/Desktop/robotics/Assets/URDF/i1/meshes/l_shoulder_roll.STL" />
      </geometry>
      <material name="">
        <color rgba="0.752941176470588 0.752941176470588 0.752941176470588 1" />
      </material>
    </visual>
    <collision>
      <origin xyz="0 0 0" rpy="0 0 0" />
      <geometry>
        <mesh filename="/data/wanshan/Desktop/robotics/Assets/URDF/i1/meshes/l_shoulder_roll.STL" />
      </geometry>
    </collision>
  </link>
  <joint name="l_shoulder_roll_joint" type="revolute">
    <origin xyz="0.028962 0.049263 -0.00085627" rpy="0 0 0" />
    <parent link="l_shoulder_pitch" />
    <child link="l_shoulder_roll" />
    <axis xyz="-0.99952 -0.0107 0.029026" />
    <limit lower="0" upper="0" effort="0" velocity="0" />
  </joint>
  <link name="l_shoulder_yaw">
    <inertial>
      <origin xyz="0.189903 0.010603 0.111571" rpy="0 0 0" />
      <mass value="0.509094" />
      <inertia ixx="0.001007" ixy="1e-06" ixz="-2.2e-05" iyy="0.000984" iyz="2.1e-05" izz="0.000262" />
    </inertial>
    <visual>
      <origin xyz="0 0 0" rpy="0 0 0" />
      <geometry>
        <mesh filename="/data/wanshan/Desktop/robotics/Assets/URDF/i1/meshes/l_shoulder_yaw.STL" />
      </geometry>
      <material name="">
        <color rgba="0.752941176470588 0.752941176470588 0.752941176470588 1" />
      </material>
    </visual>
    <collision>
      <origin xyz="0 0 0" rpy="0 0 0" />
      <geometry>
        <mesh filename="/data/wanshan/Desktop/robotics/Assets/URDF/i1/meshes/l_shoulder_yaw.STL" />
      </geometry>
    </collision>
  </link>
  <joint name="l_shoulder_yaw_joint" type="revolute">
    <origin xyz="-0.03638 -0.00038944 -0.081528" rpy="0 0 0" />
    <parent link="l_shoulder_roll" />
    <child link="l_shoulder_yaw" />
    <axis xyz="0.029024 0.0003107 0.99958" />
    <limit lower="0" upper="0" effort="0" velocity="0" />
  </joint>
  <link name="l_arm_pitch">
    <inertial>
      <origin xyz="0.187499 0.007138 -0.045974" rpy="0 0 0" />
      <mass value="0.347006" />
      <inertia ixx="0.001003" ixy="1e-06" ixz="-7.1e-05" iyy="0.000986" iyz="-5.4e-05"
        izz="0.000228" />
    </inertial>
    <visual>
      <origin xyz="0 0 0" rpy="0 0 0" />
      <geometry>
        <mesh filename="/data/wanshan/Desktop/robotics/Assets/URDF/i1/meshes/l_arm_pitch.STL" />
      </geometry>
      <material name="">
        <color rgba="0.752941176470588 0.752941176470588 0.752941176470588 1" />
      </material>
    </visual>
    <collision>
      <origin xyz="0 0 0" rpy="0 0 0" />
      <geometry>
        <mesh filename="/data/wanshan/Desktop/robotics/Assets/URDF/i1/meshes/l_arm_pitch.STL" />
      </geometry>
    </collision>
  </link>
  <joint name="l_arm_pitch_joint" type="revolute">
    <origin xyz="-0.003155 0.015492 -0.10293" rpy="0 0 0" />
    <parent link="l_shoulder_yaw" />
    <child link="l_arm_pitch" />
    <axis xyz="0.010704 -0.99994 0" />
    <limit lower="0" upper="0" effort="0" velocity="0" />
  </joint>
  <link name="head">
    <inertial>
      <origin xyz="-0.001189 0.010143 0.391397" rpy="0 0 0" />
      <mass value="0.328819" />
      <inertia ixx="0.000767" ixy="-2e-06" ixz="8e-06" iyy="0.000736" iyz="-9.8e-05" izz="0.00024" />
    </inertial>
    <visual>
      <origin xyz="0 0 0" rpy="0 0 0" />
      <geometry>
        <mesh filename="/data/wanshan/Desktop/robotics/Assets/URDF/i1/meshes/head.STL" />
      </geometry>
      <material name="">
        <color rgba="0.752941176470588 0.752941176470588 0.752941176470588 1" />
      </material>
    </visual>
    <collision>
      <origin xyz="0 0 0" rpy="0 0 0" />
      <geometry>
        <mesh filename="/data/wanshan/Desktop/robotics/Assets/URDF/i1/meshes/head.STL" />
      </geometry>
    </collision>
  </link>
  <joint name="head_joint" type="fixed">
    <origin xyz="0 0 0" rpy="0 0 0" />
    <parent link="base_link" />
    <child link="head" />
    <axis xyz="0 0 0" />
  </joint>
  <link name="imu">
    <inertial>
      <origin xyz="0.0035 3.7e-05 0.326721" rpy="0 0 0" />
      <mass value="0" />
      <inertia ixx="1e-06" ixy="-0.0" ixz="-0.0" iyy="1e-06" iyz="-0.0" izz="2e-06" />
    </inertial>
    <visual>
      <origin xyz="0 0 0" rpy="0 0 0" />
      <geometry>
        <mesh filename="/data/wanshan/Desktop/robotics/Assets/URDF/i1/meshes/imu.STL" />
      </geometry>
      <material name="">
        <color rgba="0.0627450980392157 0.517647058823529 1 1" />
      </material>
    </visual>
    <collision>
      <origin xyz="0 0 0" rpy="0 0 0" />
      <geometry>
        <mesh filename="/data/wanshan/Desktop/robotics/Assets/URDF/i1/meshes/imu.STL" />
      </geometry>
    </collision>
  </link>
  <joint name="imu_joint" type="fixed">
    <origin xyz="-3.7464E-05 0.0034998 0.26922" rpy="0 0 0.010704" />
    <parent link="base_link" />
    <child link="imu" />
    <axis xyz="0 0 0" />
  </joint>
</robot>