<?xml version="1.0" encoding="utf-8"?>
<!-- This URDF was automatically created by SolidWorks to URDF Exporter! Originally created by Stephen Brawner (brawner@gmail.com) 
     Commit Version: 1.6.0-4-g7f85cfe  Build Version: 1.6.7995.38578
     For more information, please see http://wiki.ros.org/sw_urdf_exporter -->
<robot
  name="body_0926">
  <link
    name="base_link">
    <inertial>
      <origin
        xyz="0.00131563281983566 -0.00060806258007705 0.137384875685227"
        rpy="0 0 0" />
      <mass
        value="3.59994" />
      <inertia
        ixx="0.0125609277575706"
        ixy="8.6074523392914E-05"
        ixz="-8.42121322918175E-06"
        iyy="0.00529411779355462"
        iyz="5.04444486872755E-05"
        izz="0.00917871186778057" />
    </inertial>
    <visual>
      <origin
        xyz="0 0 0"
        rpy="0 0 0" />
      <geometry>
        <mesh
          filename="package://body_0926/meshes/base_link.STL" />
      </geometry>
      <material
        name="">
        <color
          rgba="0.752941176470588 0.752941176470588 0.752941176470588 1" />
      </material>
    </visual>
    <collision>
      <origin
        xyz="0 0 0"
        rpy="0 0 0" />
      <geometry>
        <mesh
          filename="package://body_0926/meshes/base_link.STL" />
      </geometry>
    </collision>
  </link>
  <link
    name="loin_yaw">
    <inertial>
      <origin
        xyz="0.00018124055119131 4.45989171530166E-07 -0.0422741121359502"
        rpy="0 0 0" />
      <mass
        value="0.673827156984923" />
      <inertia
        ixx="0.000865199639490024"
        ixy="2.18442444592928E-09"
        ixz="-6.76749571580581E-07"
        iyy="0.000316918942470459"
        iyz="-1.90407058876183E-10"
        izz="0.000977615598081916" />
    </inertial>
    <visual>
      <origin
        xyz="0 0 0"
        rpy="0 0 0" />
      <geometry>
        <mesh
          filename="package://body_0926/meshes/loin_yaw.STL" />
      </geometry>
      <material
        name="">
        <color
          rgba="0.752941176470588 0.752941176470588 0.752941176470588 1" />
      </material>
    </visual>
    <collision>
      <origin
        xyz="0 0 0"
        rpy="0 0 0" />
      <geometry>
        <mesh
          filename="package://body_0926/meshes/loin_yaw.STL" />
      </geometry>
    </collision>
  </link>
  <joint
    name="loin_yaw_joint"
    type="fixed">
    <origin
      xyz="0 0 -0.005"
      rpy="0 0 0" />
    <parent
      link="base_link" />
    <child
      link="loin_yaw" />
    <axis
      xyz="0 0 -1" />
    <limit
      lower="0"
      upper="0"
      effort="0"
      velocity="0" />
  </joint>
  
  <!-- LEFT LEG -->
  <link
    name="leg_l1">
    <inertial>
      <origin
        xyz="0.00197214029052135 0.045437794276183 -0.000135737803479141"
        rpy="0 0 0" />
      <mass
        value="0.253607698116558" />
      <inertia
        ixx="0.000134646555335744"
        ixy="-4.20724600177779E-07"
        ixz="-6.97898398344405E-07"
        iyy="0.000119332268666788"
        iyz="6.00710204304302E-06"
        izz="0.000172847817263812" />
    </inertial>
    <visual>
      <origin
        xyz="0 0 0"
        rpy="0 0 0" />
      <geometry>
        <mesh
          filename="package://body_0926/meshes/leg_l1.STL" />
      </geometry>
      <material
        name="">
        <color
          rgba="0.752941176470588 0.752941176470588 0.752941176470588 1" />
      </material>
    </visual>
    <collision>
      <origin
        xyz="0 0 0"
        rpy="0 0 0" />
      <geometry>
        <mesh
          filename="package://body_0926/meshes/leg_l1.STL" />
      </geometry>
    </collision>
  </link>
  <joint
    name="leg_l1_joint"
    type="revolute">
    <origin
      xyz="0 0.0496000081773711 -0.0570000000004782"
      rpy="0 0 0" />
    <parent
      link="loin_yaw" />
    <child
      link="leg_l1" />
    <axis
      xyz="0 1 0" />
    <limit
      lower="-0.9"
      upper="0.9"
      effort="0"
      velocity="0" />
  </joint>
  <link
    name="leg_l2">
    <inertial>
      <origin
        xyz="-0.0291199280534827 1.06199715538408E-05 -0.0358195898363571"
        rpy="0 0 0" />
      <mass
        value="0.095901931709411" />
      <inertia
        ixx="7.92420218445345E-05"
        ixy="-1.6051411236E-09"
        ixz="3.29673030281462E-06"
        iyy="0.000130635930759485"
        iyz="-2.59226913077532E-10"
        izz="0.000110945157204442" />
    </inertial>
    <visual>
      <origin
        xyz="0 0 0"
        rpy="0 0 0" />
      <geometry>
        <mesh
          filename="package://body_0926/meshes/leg_l2.STL" />
      </geometry>
      <material
        name="">
        <color
          rgba="0.752941176470588 0.752941176470588 0.752941176470588 1" />
      </material>
    </visual>
    <collision>
      <origin
        xyz="0 0 0"
        rpy="0 0 0" />
      <geometry>
        <mesh
          filename="package://body_0926/meshes/leg_l2.STL" />
      </geometry>
    </collision>
  </link>
  <joint
    name="leg_l2_joint"
    type="revolute">
    <origin
      xyz="0.0271000000005301 0.0459499999996874 0"
      rpy="0 0 0" />
    <parent
      link="leg_l1" />
    <child
      link="leg_l2" />
    <axis
      xyz="-1 0 0" />
    <limit
      lower="-0.05"
      upper="0.7"
      effort="0"
      velocity="0" />
  </joint>
  <link
    name="leg_l3">
    <inertial>
      <origin
        xyz="-0.00016856314603382 0.000798704678838885 -0.0701267665233698"
        rpy="0 0 0" />
      <mass
        value="0.460279230794127" />
      <inertia
        ixx="0.000682352933385247"
        ixy="1.70304725927578E-07"
        ixz="2.56310995795999E-06"
        iyy="0.000590581387510956"
        iyz="-1.36619744379625E-05"
        izz="0.000230566473840614" />
    </inertial>
    <visual>
      <origin
        xyz="0 0 0"
        rpy="0 0 0" />
      <geometry>
        <mesh
          filename="package://body_0926/meshes/leg_l3.STL" />
      </geometry>
      <material
        name="">
        <color
          rgba="0.752941176470588 0.752941176470588 0.752941176470588 1" />
      </material>
    </visual>
    <collision>
      <origin
        xyz="0 0 0"
        rpy="0 0 0" />
      <geometry>
        <mesh
          filename="package://body_0926/meshes/leg_l3.STL" />
      </geometry>
    </collision>
  </link>
  <joint
    name="leg_l3_joint"
    type="revolute">
    <origin
      xyz="-0.0271499999934677 0 -0.0740000000023893"
      rpy="0 0 0" />
    <parent
      link="leg_l2" />
    <child
      link="leg_l3" />
    <axis
      xyz="0 0 -1" />
    <limit
      lower="-0.8"
      upper="0.8"
      effort="0"
      velocity="0" />
  </joint>
  <link
    name="leg_l4">
    <inertial>
      <origin
        xyz="-0.0022770236151511 -0.0277883611099162 -0.0826474110106563"
        rpy="0 0 0" />
      <mass
        value="0.25780252501563" />
      <inertia
        ixx="0.000497168127288963"
        ixy="-1.4623827708905E-08"
        ixz="-2.65637263268134E-07"
        iyy="0.000536858117604927"
        iyz="3.21405738706319E-07"
        izz="7.8367679028294E-05" />
    </inertial>
    <visual>
      <origin
        xyz="0 0 0"
        rpy="0 0 0" />
      <geometry>
        <mesh
          filename="package://body_0926/meshes/leg_l4.STL" />
      </geometry>
      <material
        name="">
        <color
          rgba="0.752941176470588 0.752941176470588 0.752941176470588 1" />
      </material>
    </visual>
    <collision>
      <origin
        xyz="0 0 0"
        rpy="0 0 0" />
      <geometry>
        <mesh
          filename="package://body_0926/meshes/leg_l4.STL" />
      </geometry>
    </collision>
  </link>
  <joint
    name="leg_l4_joint"
    type="revolute">
    <origin
      xyz="0 0.0271000000001188 -0.117049999999972"
      rpy="0 0 0" />
    <parent
      link="leg_l3" />
    <child
      link="leg_l4" />
    <axis
      xyz="0 -1 0" />
    <limit
      lower="-0.1"
      upper="1.8"
      effort="0"
      velocity="0" />
  </joint>
  <link
    name="leg_l5">
    <inertial>
      <origin
        xyz="0.0145611828344786 -0.0199995601688862 -0.0137651899210866"
        rpy="0 0 0" />
      <mass
        value="0.136735951104808" />
      <inertia
        ixx="4.75431777108231E-05"
        ixy="-1.14018535984589E-09"
        ixz="1.97672677577001E-05"
        iyy="0.000294200183998198"
        iyz="4.2501915806706E-11"
        izz="0.000313378471806043" />
    </inertial>
    <visual>
      <origin
        xyz="0 0 0"
        rpy="0 0 0" />
      <geometry>
        <mesh
          filename="package://body_0926/meshes/leg_l5.STL" />
      </geometry>
      <material
        name="">
        <color
          rgba="0.752941176470588 0.752941176470588 0.752941176470588 1" />
      </material>
    </visual>
    <collision>
      <origin
        xyz="0 0 0"
        rpy="0 0 0" />
      <geometry>
        <mesh
          filename="package://body_0926/meshes/leg_l5.STL" />
      </geometry>
    </collision>
  </link>
  <joint
    name="leg_l5_joint"
    type="revolute">
    <origin
      xyz="0 -0.00709999999740331 -0.200000000000092"
      rpy="0 0 0" />
    <parent
      link="leg_l4" />
    <child
      link="leg_l5" />
    <axis
      xyz="0 -1 0" />
    <limit
      lower="0.3"
      upper="0.9"
      effort="0"
      velocity="0" />
  </joint>
  
  <!-- RIGHT LEG -->
  <link
    name="leg_r1">
    <inertial>
      <origin
        xyz="0.00197049603022036 -0.0454676335467138 -0.000147016961480978"
        rpy="0 0 0" />
      <mass
        value="0.253409170777096" />
      <inertia
        ixx="0.000134320103357949"
        ixy="4.30374879394354E-07"
        ixz="-6.97529823794351E-07"
        iyy="0.000119287556302132"
        iyz="-6.04520755774105E-06"
        izz="0.00017253471653123" />
    </inertial>
    <visual>
      <origin
        xyz="0 0 0"
        rpy="0 0 0" />
      <geometry>
        <mesh
          filename="package://body_0926/meshes/leg_r1.STL" />
      </geometry>
      <material
        name="">
        <color
          rgba="0.752941176470588 0.752941176470588 0.752941176470588 1" />
      </material>
    </visual>
    <collision>
      <origin
        xyz="0 0 0"
        rpy="0 0 0" />
      <geometry>
        <mesh
          filename="package://body_0926/meshes/leg_r1.STL" />
      </geometry>
    </collision>
  </link>
  <joint
    name="leg_r1_joint"
    type="revolute">
    <origin
      xyz="0 -0.0495999918226289 -0.0569999999995216"
      rpy="0 0 0" />
    <parent
      link="loin_yaw" />
    <child
      link="leg_r1" />
    <axis
      xyz="0 1 0" />
    <limit
      lower="0"
      upper="0"
      effort="0"
      velocity="0" />
  </joint>
  <link
    name="leg_r2">
    <inertial>
      <origin
        xyz="-0.029119928056649 1.06199715543542E-05 -0.0358224011508697"
        rpy="0 0 0" />
      <mass
        value="0.0959019317094106" />
      <inertia
        ixx="7.92420218451148E-05"
        ixy="-1.60514112734303E-09"
        ixz="3.29673030560823E-06"
        iyy="0.000130635930759484"
        iyz="-2.59226906723774E-10"
        izz="0.00011094515720386" />
    </inertial>
    <visual>
      <origin
        xyz="0 0 0"
        rpy="0 0 0" />
      <geometry>
        <mesh
          filename="package://body_0926/meshes/leg_r2.STL" />
      </geometry>
      <material
        name="">
        <color
          rgba="0.752941176470588 0.752941176470588 0.752941176470588 1" />
      </material>
    </visual>
    <collision>
      <origin
        xyz="0 0 0"
        rpy="0 0 0" />
      <geometry>
        <mesh
          filename="package://body_0926/meshes/leg_r2.STL" />
      </geometry>
    </collision>
  </link>
  <joint
    name="leg_r2_joint"
    type="revolute">
    <origin
      xyz="0.0270999999994667 -0.0459500000003151 0"
      rpy="0 0 0" />
    <parent
      link="leg_r1" />
    <child
      link="leg_r2" />
    <axis
      xyz="-1 0 0" />
    <limit
      lower="0"
      upper="0"
      effort="0"
      velocity="0" />
  </joint>
  <link
    name="leg_r3">
    <inertial>
      <origin
        xyz="0.000284853772726906 -0.00079869955661363 -0.0701274345182918"
        rpy="0 0 0" />
      <mass
        value="0.460279200579914" />
      <inertia
        ixx="0.000682463230739524"
        ixy="-9.64403372512498E-08"
        ixz="-1.87540751657078E-06"
        iyy="0.00059068616274301"
        iyz="1.36822825719233E-05"
        izz="0.000230563117110192" />
    </inertial>
    <visual>
      <origin
        xyz="0 0 0"
        rpy="0 0 0" />
      <geometry>
        <mesh
          filename="package://body_0926/meshes/leg_r3.STL" />
      </geometry>
      <material
        name="">
        <color
          rgba="0.752941176470588 0.752941176470588 0.752941176470588 1" />
      </material>
    </visual>
    <collision>
      <origin
        xyz="0 0 0"
        rpy="0 0 0" />
      <geometry>
        <mesh
          filename="package://body_0926/meshes/leg_r3.STL" />
      </geometry>
    </collision>
  </link>
  <joint
    name="leg_r3_joint"
    type="revolute">
    <origin
      xyz="-0.0271499999999982 0 -0.0740526859428612"
      rpy="0 0 0" />
    <parent
      link="leg_r2" />
    <child
      link="leg_r3" />
    <axis
      xyz="0 0 -1" />
    <limit
      lower="0"
      upper="0"
      effort="0"
      velocity="0" />
  </joint>
  <link
    name="leg_r4">
    <inertial>
      <origin
        xyz="-0.0022501356623442 0.027836860837675 -0.0826474112194918"
        rpy="0 0 0" />
      <mass
        value="0.25780252501563" />
      <inertia
        ixx="0.000497168127032598"
        ixy="-1.46271564143886E-08"
        ixz="2.65637586585301E-07"
        iyy="0.000536858117605106"
        iyz="-3.2139130718811E-07"
        izz="7.83676792844901E-05" />
    </inertial>
    <visual>
      <origin
        xyz="0 0 0"
        rpy="0 0 0" />
      <geometry>
        <mesh
          filename="package://body_0926/meshes/leg_r4.STL" />
      </geometry>
      <material
        name="">
        <color
          rgba="0.752941176470588 0.752941176470588 0.752941176470588 1" />
      </material>
    </visual>
    <collision>
      <origin
        xyz="0 0 0"
        rpy="0 0 0" />
      <geometry>
        <mesh
          filename="package://body_0926/meshes/leg_r4.STL" />
      </geometry>
    </collision>
  </link>
  <joint
    name="leg_r4_joint"
    type="revolute">
    <origin
      xyz="0 -0.0270999999988379 -0.117050000000269"
      rpy="0 0 0" />
    <parent
      link="leg_r3" />
    <child
      link="leg_r4" />
    <axis
      xyz="0 1 0" />
    <limit
      lower="0"
      upper="0"
      effort="0"
      velocity="0" />
  </joint>
  <link
    name="leg_r5">
    <inertial>
      <origin
        xyz="0.0145611828345078 0.0200004398309187 -0.0137651899206686"
        rpy="0 0 0" />
      <mass
        value="0.136735951104807" />
      <inertia
        ixx="4.75431777118671E-05"
        ixy="-1.14018533817084E-09"
        ixz="1.97672677646035E-05"
        iyy="0.000294200183998192"
        iyz="4.2501936084229E-11"
        izz="0.000313378471805028" />
    </inertial>
    <visual>
      <origin
        xyz="0 0 0"
        rpy="0 0 0" />
      <geometry>
        <mesh
          filename="package://body_0926/meshes/leg_r5.STL" />
      </geometry>
      <material
        name="">
        <color
          rgba="0.752941176470588 0.752941176470588 0.752941176470588 1" />
      </material>
    </visual>
    <collision>
      <origin
        xyz="0 0 0"
        rpy="0 0 0" />
      <geometry>
        <mesh
          filename="package://body_0926/meshes/leg_r5.STL" />
      </geometry>
    </collision>
  </link>
  <joint
    name="leg_r5_joint"
    type="revolute">
    <origin
      xyz="0 0.00715000000367917 -0.200000000000334"
      rpy="0 0 0" />
    <parent
      link="leg_r4" />
    <child
      link="leg_r5" />
    <axis
      xyz="0 1 0" />
    <limit
      lower="0"
      upper="0"
      effort="0"
      velocity="0" />
  </joint>
  
  <!-- RIGHT HAND -->
  <link
    name="r_shoulder_pitch">
    <inertial>
      <origin
        xyz="-0.00492132319550564 -0.044268005455759 -7.2502679317521E-05"
        rpy="0 0 0" />
      <mass
        value="0.141054886694359" />
      <inertia
        ixx="6.8439363365992E-05"
        ixy="-5.90002631999263E-06"
        ixz="1.73988328907595E-07"
        iyy="5.07634606888042E-05"
        iyz="-6.47486444761441E-08"
        izz="5.86465949480007E-05" />
    </inertial>
    <visual>
      <origin
        xyz="0 0 0"
        rpy="0 0 0" />
      <geometry>
        <mesh
          filename="package://body_0926/meshes/r_shoulder_pitch.STL" />
      </geometry>
      <material
        name="">
        <color
          rgba="0.752941176470588 0.752941176470588 0.752941176470588 1" />
      </material>
    </visual>
    <collision>
      <origin
        xyz="0 0 0"
        rpy="0 0 0" />
      <geometry>
        <mesh
          filename="package://body_0926/meshes/r_shoulder_pitch.STL" />
      </geometry>
    </collision>
  </link>
  <joint
    name="r_shoulder_pitch_joint"
    type="revolute">
    <origin
      xyz="0.00152114352789188 -0.142100042363837 0.19235627367497"
      rpy="0 0 0.0107043277626806" />
    <parent
      link="base_link" />
    <child
      link="r_shoulder_pitch" />
    <axis
      xyz="0 1 0" />
    <limit
      lower="0"
      upper="0"
      effort="0"
      velocity="0" />
  </joint>
  <link
    name="r_shoulder_roll">
    <inertial>
      <origin
        xyz="-0.035710709246885 -0.000382189682273965 -0.0451844388918135"
        rpy="0 0 0" />
      <mass
        value="0.123184086798306" />
      <inertia
        ixx="0.000103300324672962"
        ixy="-1.6943498620183E-07"
        ixz="5.28116322274124E-06"
        iyy="0.000119033335984562"
        iyz="5.62487587688296E-08"
        izz="0.000110829718571304" />
    </inertial>
    <visual>
      <origin
        xyz="0 0 0"
        rpy="0 0 0" />
      <geometry>
        <mesh
          filename="package://body_0926/meshes/r_shoulder_roll.STL" />
      </geometry>
      <material
        name="">
        <color
          rgba="0.752941176470588 0.752941176470588 0.752941176470588 1" />
      </material>
    </visual>
    <collision>
      <origin
        xyz="0 0 0"
        rpy="0 0 0" />
      <geometry>
        <mesh
          filename="package://body_0926/meshes/r_shoulder_roll.STL" />
      </geometry>
    </collision>
  </link>
  <joint
    name="r_shoulder_roll_joint"
    type="revolute">
    <origin
      xyz="0.0294988163604422 -0.0489500000001077 0.000264259939019407"
      rpy="0 0 -0.0107043277626806" />
    <parent
      link="r_shoulder_pitch" />
    <child
      link="r_shoulder_roll" />
    <axis
      xyz="0.999902588164708 0.010703693844858 0.00895796403171279" />
    <limit
      lower="0"
      upper="0"
      effort="0"
      velocity="0" />
  </joint>
  <link
    name="r_shoulder_yaw">
    <inertial>
      <origin
        xyz="0.000629566408822935 0.000347051398751186 -0.0606680778460377"
        rpy="0 0 0" />
      <mass
        value="0.318561871627575" />
      <inertia
        ixx="0.000405107602336148"
        ixy="7.37786054759943E-07"
        ixz="2.62531563885042E-06"
        iyy="0.000343493131252904"
        iyz="-4.37154455876503E-06"
        izz="0.000127543264547697" />
    </inertial>
    <visual>
      <origin
        xyz="0 0 0"
        rpy="0 0 0" />
      <geometry>
        <mesh
          filename="package://body_0926/meshes/r_shoulder_yaw.STL" />
      </geometry>
      <material
        name="">
        <color
          rgba="0.752941176470588 0.752941176470588 0.752941176470588 1" />
      </material>
    </visual>
    <collision>
      <origin
        xyz="0 0 0"
        rpy="0 0 0" />
      <geometry>
        <mesh
          filename="package://body_0926/meshes/r_shoulder_yaw.STL" />
      </geometry>
    </collision>
  </link>
  <joint
    name="r_shoulder_yaw_joint"
    type="revolute">
    <origin
      xyz="-0.0332572504317691 -0.000356010107427529 -0.0828512585933959"
      rpy="0 0 0" />
    <parent
      link="r_shoulder_roll" />
    <child
      link="r_shoulder_yaw" />
    <axis
      xyz="0.0290244273796275 0.000310698861993819 0.999578654274641" />
    <limit
      lower="0"
      upper="0"
      effort="0"
      velocity="0" />
  </joint>
  <link
    name="r_arm_pitch">
    <inertial>
      <origin
        xyz="-0.000120887489620346 0.0204861676811988 -0.115111785374582"
        rpy="0 0 0" />
      <mass
        value="0.347021103046602" />
      <inertia
        ixx="0.000410229626992532"
        ixy="4.32416766599604E-06"
        ixz="9.6318814764432E-06"
        iyy="0.000425084681831462"
        iyz="4.48297705694217E-05"
        izz="0.000223372198626179" />
    </inertial>
    <visual>
      <origin
        xyz="0 0 0"
        rpy="0 0 0" />
      <geometry>
        <mesh
          filename="package://body_0926/meshes/r_arm_pitch.STL" />
      </geometry>
      <material
        name="">
        <color
          rgba="0.752941176470588 0.752941176470588 0.752941176470588 1" />
      </material>
    </visual>
    <collision>
      <origin
        xyz="0 0 0"
        rpy="0 0 0" />
      <geometry>
        <mesh
          filename="package://body_0926/meshes/r_arm_pitch.STL" />
      </geometry>
    </collision>
  </link>
  <joint
    name="r_arm_pitch_joint"
    type="revolute">
    <origin
      xyz="0.00108857599788274 -0.0155142365719634 -0.102970782946762"
      rpy="0 0 0" />
    <parent
      link="r_shoulder_yaw" />
    <child
      link="r_arm_pitch" />
    <axis
      xyz="0.010704123340247 -0.999942709230642 0" />
    <limit
      lower="0"
      upper="0"
      effort="0"
      velocity="0" />
  </joint>
  
  <!-- LEFT HAND -->
  <link
    name="l_shoulder_pitch">
    <inertial>
      <origin
        xyz="-0.00539414014774459 0.0442128106968985 0.000114466943134106"
        rpy="0 0 0" />
      <mass
        value="0.14105595500497" />
      <inertia
        ixx="6.83104946942008E-05"
        ixy="6.08605439164582E-06"
        ixz="-1.96441410303778E-07"
        iyy="5.08921309626767E-05"
        iyz="-1.61488441045236E-07"
        izz="5.86479470158344E-05" />
    </inertial>
    <visual>
      <origin
        xyz="0 0 0"
        rpy="0 0 0" />
      <geometry>
        <mesh
          filename="package://body_0926/meshes/l_shoulder_pitch.STL" />
      </geometry>
      <material
        name="">
        <color
          rgba="0.752941176470588 0.752941176470588 0.752941176470588 1" />
      </material>
    </visual>
    <collision>
      <origin
        xyz="0 0 0"
        rpy="0 0 0" />
      <geometry>
        <mesh
          filename="package://body_0926/meshes/l_shoulder_pitch.STL" />
      </geometry>
    </collision>
  </link>
  <joint
    name="l_shoulder_pitch_joint"
    type="revolute">
    <origin
      xyz="-0.00152114352789363 0.142100042367547 0.192356273672232"
      rpy="0 0 0" />
    <parent
      link="base_link" />
    <child
      link="l_shoulder_pitch" />
    <axis
      xyz="-0.0107041233402471 0.999942709230642 0" />
    <limit
      lower="0"
      upper="0"
      effort="0"
      velocity="0" />
  </joint>
  <link
    name="l_shoulder_roll">
    <inertial>
      <origin
        xyz="-0.0374009834849709 -0.000400402282130535 -0.043796002059575"
        rpy="0 0 0" />
      <mass
        value="0.123182291911097" />
      <inertia
        ixx="0.000103709972990609"
        ixy="-1.6367309324254E-07"
        ixz="5.55177520515811E-06"
        iyy="0.000119028566294749"
        iyz="5.94436926630934E-08"
        izz="0.000110416448323271" />
    </inertial>
    <visual>
      <origin
        xyz="0 0 0"
        rpy="0 0 0" />
      <geometry>
        <mesh
          filename="package://body_0926/meshes/l_shoulder_roll.STL" />
      </geometry>
      <material
        name="">
        <color
          rgba="0.752941176470588 0.752941176470588 0.752941176470588 1" />
      </material>
    </visual>
    <collision>
      <origin
        xyz="0 0 0"
        rpy="0 0 0" />
      <geometry>
        <mesh
          filename="package://body_0926/meshes/l_shoulder_roll.STL" />
      </geometry>
    </collision>
  </link>
  <joint
    name="l_shoulder_roll_joint"
    type="revolute">
    <origin
      xyz="0.028961914097807 0.0492628342080569 -0.000856269663819131"
      rpy="0 0 0" />
    <parent
      link="l_shoulder_pitch" />
    <child
      link="l_shoulder_roll" />
    <axis
      xyz="-0.999521387644461 -0.0106996131992724 0.0290260903098726" />
    <limit
      lower="0"
      upper="0"
      effort="0"
      velocity="0" />
  </joint>
  <link
    name="l_shoulder_yaw">
    <inertial>
      <origin
        xyz="-0.0016462794201702 -0.000353572153722337 -0.0606399089506535"
        rpy="0 0 0" />
      <mass
        value="0.318908095271848" />
      <inertia
        ixx="0.00040489673882892"
        ixy="7.45538282891033E-07"
        ixz="-8.00967011367204E-06"
        iyy="0.000343473854045599"
        iyz="4.31361045605922E-06"
        izz="0.000127757861965924" />
    </inertial>
    <visual>
      <origin
        xyz="0 0 0"
        rpy="0 0 0" />
      <geometry>
        <mesh
          filename="package://body_0926/meshes/l_shoulder_yaw.STL" />
      </geometry>
      <material
        name="">
        <color
          rgba="0.752941176470588 0.752941176470588 0.752941176470588 1" />
      </material>
    </visual>
    <collision>
      <origin
        xyz="0 0 0"
        rpy="0 0 0" />
      <geometry>
        <mesh
          filename="package://body_0926/meshes/l_shoulder_yaw.STL" />
      </geometry>
    </collision>
  </link>
  <joint
    name="l_shoulder_yaw_joint"
    type="revolute">
    <origin
      xyz="-0.0363796936599959 -0.000389435038538916 -0.0815283308399195"
      rpy="0 0 0" />
    <parent
      link="l_shoulder_roll" />
    <child
      link="l_shoulder_yaw" />
    <axis
      xyz="0.0290244273796269 0.000310698860122039 0.999578654274641" />
    <limit
      lower="0"
      upper="0"
      effort="0"
      velocity="0" />
  </joint>
  <link
    name="l_arm_pitch">
    <inertial>
      <origin
        xyz="0.00507392834432305 -0.0204329157543131 -0.115009957051898"
        rpy="0 0 0" />
      <mass
        value="0.34701674698604" />
      <inertia
        ixx="0.000409237731987876"
        ixy="-2.83182057213379E-06"
        ixz="1.81472025853559E-05"
        iyy="0.000424924800463279"
        iyz="-4.4670678171571E-05"
        izz="0.000224499231540757" />
    </inertial>
    <visual>
      <origin
        xyz="0 0 0"
        rpy="0 0 0" />
      <geometry>
        <mesh
          filename="package://body_0926/meshes/l_arm_pitch.STL" />
      </geometry>
      <material
        name="">
        <color
          rgba="0.752941176470588 0.752941176470588 0.752941176470588 1" />
      </material>
    </visual>
    <collision>
      <origin
        xyz="0 0 0"
        rpy="0 0 0" />
      <geometry>
        <mesh
          filename="package://body_0926/meshes/l_arm_pitch.STL" />
      </geometry>
    </collision>
  </link>
  <joint
    name="l_arm_pitch_joint"
    type="revolute">
    <origin
      xyz="-0.00315495415371205 0.0154921165359136 -0.10293149731973"
      rpy="0 0 0" />
    <parent
      link="l_shoulder_yaw" />
    <child
      link="l_arm_pitch" />
    <axis
      xyz="0.010704123340247 -0.999942709230642 0" />
    <limit
      lower="0"
      upper="0"
      effort="0"
      velocity="0" />
  </joint>
  <link
    name="head">
    <inertial>
      <origin
        xyz="-0.00701349825938762 5.17059253729681E-05 0.31307144450079"
        rpy="0 0 0" />
      <mass
        value="0.288024463101203" />
      <inertia
        ixx="0.000169238006866538"
        ixy="1.01060376341253E-06"
        ixz="1.54904531269208E-05"
        iyy="0.000160937804146975"
        iyz="-1.33972897592594E-05"
        izz="0.000145954734810219" />
    </inertial>
    <visual>
      <origin
        xyz="0 0 0"
        rpy="0 0 0" />
      <geometry>
        <mesh
          filename="package://body_0926/meshes/head.STL" />
      </geometry>
      <material
        name="">
        <color
          rgba="0.752941176470588 0.752941176470588 0.752941176470588 1" />
      </material>
    </visual>
    <collision>
      <origin
        xyz="0 0 0"
        rpy="0 0 0" />
      <geometry>
        <mesh
          filename="package://body_0926/meshes/head.STL" />
      </geometry>
    </collision>
  </link>
  <joint
    name="head_joint"
    type="fixed">
    <origin
      xyz="0 0 0"
      rpy="0 0 0" />
    <parent
      link="base_link" />
    <child
      link="head" />
    <axis
      xyz="0 0 0" />
  </joint>
</robot>