<mujoco model="i1_1101_full_body"> 
  <compiler meshdir="../mjcf_meshes/" angle="radian"
  autolimits="true" eulerseq="zyx" /> <option timestep='0.001' iterations='50' solver='PGS'
    gravity='0 0 -9.81'>
    <!-- <flag sensornoise="enable" frictionloss="enable" /> -->
  </option>
  <size njmax="500" nconmax="100" />
<visual>
    <quality shadowsize='4096' />
    <map znear='0.05' />
  </visual>
  <default>
    <joint limited='true' />
    <motor ctrllimited='true' />
    <geom condim='4' contype="1" conaffinity="15" solref='0.001 2' friction='0.9 0.2 0.2' />
    <equality solref='0.001 2' />
    <!-- <default class='leg_joint_param'>
      <joint damping="0.01" frictionloss="0.01" armature="0.01" />
    </default> -->
  </default>
  <statistic meansize="0.164352" extent="1.07561"
    center="-0.00820016 -1.48012e-05 -0.160784" />
  <asset>
    <mesh name="base_link" file="base_link.STL" />
    <mesh name="loin_yaw" file="loin_yaw.STL" />
    <mesh name="leg_l1" file="leg_l1.STL" />
    <mesh name="leg_l2" file="leg_l2.STL" />
    <mesh name="leg_l3" file="leg_l3.STL" />
    <mesh name="leg_l4" file="leg_l4.STL" />
    <mesh name="leg_l5" file="leg_l5.STL" />
    <mesh name="leg_r1" file="leg_r1.STL" />
    <mesh name="leg_r2" file="leg_r2.STL" />
    <mesh name="leg_r3" file="leg_r3.STL" />
    <mesh name="leg_r4" file="leg_r4.STL" />
    <mesh name="leg_r5" file="leg_r5.STL" />
    <mesh name="r_shoulder_pitch" file="r_shoulder_pitch.STL" />
    <mesh name="r_shoulder_roll" file="r_shoulder_roll.STL" />
    <mesh name="r_shoulder_yaw" file="r_shoulder_yaw.STL" />
    <mesh name="r_arm_pitch" file="r_arm_pitch.STL" />
    <mesh name="l_shoulder_pitch" file="l_shoulder_pitch.STL" />
    <mesh name="l_shoulder_roll" file="l_shoulder_roll.STL" />
    <mesh name="l_shoulder_yaw" file="l_shoulder_yaw.STL" />
    <mesh name="l_arm_pitch" file="l_arm_pitch.STL" />
    <mesh name="head" file="head.STL" />
    <mesh name="imu" file="imu.STL" />
    <material name="matplane" reflectance="0.3" texture="texplane" texrepeat="1 1"
      texuniform="true" />
    <material name="matgeom" texture="texgeom" texuniform="true" rgba="0.8 0.6 .4 1" />
    <texture name="texplane" type="2d" builtin="checker" rgb1=".2 .3 .4" rgb2=".1 0.15 0.2"
      width="512" height="512" mark="cross" markrgb=".8 .8 .8" />
    <texture name="texgeom" type="cube" builtin="flat" mark="cross" width="127" height="1278"
      rgb1="0.8 0.6 0.4" rgb2="0.8 0.6 0.4" markrgb="1 1 1" random="0.01" />
    <texture type="skybox" builtin="gradient" rgb1="1 1 1" rgb2=".6 .8 1" width="256"
      height="256" />
  </asset>

  <worldbody>
    <!-- light and ground -->
    <light directional="true" diffuse=".4 .4 .4" specular="0.1 0.1 0.1" pos="0 0 5.0"
      dir="0 0 -1" castshadow="false" />
    <light directional="true" diffuse=".6 .6 .6" specular="0.2 0.2 0.2" pos="0 0 4" dir="0 0 -1" />
    <geom name="ground" type="plane" size="0 0 1" pos="0.001 0 0" quat="1 0 0 0"
      material="matplane" condim="1" conaffinity='15' />
    <!-- robot -->
    <body name="base_link" pos="0 0 0.46">
      <inertial pos="0.000359611 -0.00492366 0.0901198"
        quat="0.999448 0.032519 0.00652246 0.00189336" mass="5.45643"
        diaginertia="0.0747614 0.0606222 0.0237786" />
      <joint name="floating_base_joint" type="free" />
      <!-- imu -->
      <site name='imu' size='0.01' pos='-0.000112387 0.006999 0.269221' quat='0.999943 0 0 0.010704' />
      <geom type="mesh" contype="0" conaffinity="0" group="1" density="0"
        rgba="0.75294 0.75294 0.75294 1" mesh="base_link" />
      <geom type="mesh" rgba="0.75294 0.75294 0.75294 1" mesh="base_link" />
      <geom type="mesh" contype="0" conaffinity="0" group="1" density="0"
        rgba="0.75294 0.75294 0.75294 1" mesh="loin_yaw" />
      <geom type="mesh" rgba="0.75294 0.75294 0.75294 1" mesh="loin_yaw" />
      <geom pos="-3.7464e-05 0.0034998 0" quat="0.999986 0 0 0.00535197" type="mesh" contype="0"
        conaffinity="0" group="1" density="0" rgba="0.752941 0.752941 0.752941 1" mesh="head" />
      <geom pos="-3.7464e-05 0.0034998 0" quat="0.999986 0 0 0.00535197" type="mesh"
        rgba="0.752941 0.752941 0.752941 1" mesh="head" />
      <!-- imu visual -->
      <geom pos="-0.000112387 0.006999 0.269221" quat="0.999943 0 0 0.010704" type="mesh"
        contype="0" conaffinity="0" group="1" density="0" rgba="1 1 1 1" mesh="imu" />
      <geom pos="-0.000112387 0.006999 0.269221" quat="0.999943 0 0 0.010704" type="mesh"
        rgba="1 1 1 1" mesh="imu" />
      <body name="leg_l1" pos="0 0.0496 -0.062" quat="0.984727 0 -0.174108 0">
        <inertial pos="0.004066 0.045668 -6.7e-05" quat="0.663477 0.727246 -0.0055201 -0.175729"
          mass="0.510247" diaginertia="0.000292779 0.000288767 0.000284454" />
        <joint name="leg_l1_joint" pos="0 0 0" axis="0 1 0" range="-0.7 0.9" />
        <geom type="mesh" contype="0" conaffinity="0" group="1" density="0"
          rgba="0.752941 0.752941 0.752941 1" mesh="leg_l1" />
        <geom type="mesh" rgba="0.752941 0.752941 0.752941 1" mesh="leg_l1" />
        <body name="leg_l2" pos="0.0271 0.04595 0">
          <inertial pos="-0.02912 1.2e-05 -0.03582" quat="0.424386 0.565594 0.565594 0.424386"
            mass="0.095898" diaginertia="0.00016 0.000123038 9.69616e-05" />
          <joint name="leg_l2_joint" pos="0 0 0" axis="-1 0 0" range="-0.7 0" />
          <geom type="mesh" contype="0" conaffinity="0" group="1" density="0"
            rgba="0.752941 0.752941 0.752941 1" mesh="leg_l2" />
          <body name="leg_l3" pos="-0.02715 0 -0.074">
            <inertial pos="0.000149 0.001981 -0.070577"
              quat="0.997263 0.0236554 -0.00368969 0.0699464" mass="0.97356"
              diaginertia="0.00250523 0.00249525 0.000543527" />
            <joint name="leg_l3_joint" pos="0 0 0" axis="0 0 -1" range="-0.8 0.8" />
            <geom type="mesh" contype="0" conaffinity="0" group="1" density="0"
              rgba="0.752941 0.752941 0.752941 1" mesh="leg_l3" />
            <geom type="mesh" rgba="0.752941 0.752941 0.752941 1" mesh="leg_l3" />
            <body name="leg_l4" pos="0 0.0271 -0.11705" quat="0.939373 0 0.342898 0">
              <inertial pos="-0.001168 -0.029747 -0.081327"
                quat="0.999445 0.0138236 0.0293768 0.00748705" mass="0.514444"
                diaginertia="0.000850732 0.000765281 0.000356988" />
              <joint name="leg_l4_joint" pos="0 0 0" axis="0 1 0" range="-0.1 1.6" />
              <geom type="mesh" contype="0" conaffinity="0" group="1" density="0"
                rgba="0.752941 0.752941 0.752941 1" mesh="leg_l4" />
              <body name="leg_l5" pos="0 -0.0071 -0.2" quat="0.984727 0 -0.174108 0">
                <inertial pos="0.014563 -0.02 -0.013765" quat="0 0.73395 0 0.679204" mass="0.136733"
                  diaginertia="0.00031963 0.000298 4.73705e-05" />
                <joint name="leg_l5_joint" pos="0 0 0" axis="0 1 0" range="-0.9 0.2" />
                <geom type="mesh" contype="0" conaffinity="0" group="1" density="0"
                  rgba="0.752941 0.752941 0.752941 1" mesh="leg_l5" />
                <geom type="mesh" rgba="0.752941 0.752941 0.752941 1" mesh="leg_l5" />
              </body>
            </body>
          </body>
        </body>
      </body>
      <body name="leg_r1" pos="0 -0.0496 -0.062" quat="0.984727 0 -0.174108 0">
        <inertial pos="0.004066 -0.045683 -7.4e-05" quat="0.735352 0.65184 0.184079 0.021855"
          mass="0.510049" diaginertia="0.000291845 0.000287785 0.00028437" />
        <joint name="leg_r1_joint" pos="0 0 0" axis="0 1 0" range="-0.7 0.9" />
        <geom type="mesh" contype="0" conaffinity="0" group="1" density="0"
          rgba="0.752941 0.752941 0.752941 1" mesh="leg_r1" />
        <geom type="mesh" rgba="0.752941 0.752941 0.752941 1" mesh="leg_r1" />
        <body name="leg_r2" pos="0.0271 -0.04595 0">
          <inertial pos="-0.02912 1.2e-05 -0.035822" quat="0.424386 0.565594 0.565594 0.424386"
            mass="0.095898" diaginertia="0.00016 0.000123038 9.69616e-05" />
          <joint name="leg_r2_joint" pos="0 0 0" axis="-1 0 0" range="0 0.7" />
          <geom type="mesh" contype="0" conaffinity="0" group="1" density="0"
            rgba="0.752941 0.752941 0.752941 1" mesh="leg_r2" />
          <body name="leg_r3" pos="-0.02715 0 -0.0740527">
            <inertial pos="0.000149 -0.001981 -0.070578"
              quat="0.998839 -0.0238793 3.16623e-05 -0.0418364" mass="0.97356"
              diaginertia="0.00250508 0.00249537 0.00054355" />
            <joint name="leg_r3_joint" pos="0 0 0" axis="0 0 -1" range="-0.8 0.8" />
            <geom type="mesh" contype="0" conaffinity="0" group="1" density="0"
              rgba="0.752941 0.752941 0.752941 1" mesh="leg_r3" />
            <geom type="mesh" rgba="0.752941 0.752941 0.752941 1" mesh="leg_r3" />
            <body name="leg_r4" pos="0 -0.0271 -0.11705" quat="0.939373 0 0.342898 0">
              <inertial pos="-0.001101 0.029796 -0.081327"
                quat="0.999382 -0.0140673 0.0293224 -0.0133131" mass="0.514444"
                diaginertia="0.000850775 0.000765241 0.000356985" />
              <joint name="leg_r4_joint" pos="0 0 0" axis="0 1 0" range="-0.1 1.6" />
              <geom type="mesh" contype="0" conaffinity="0" group="1" density="0"
                rgba="0.752941 0.752941 0.752941 1" mesh="leg_r4" />
              <body name="leg_r5" pos="0 0.00715 -0.2" quat="0.984727 0 -0.174108 0">
                <inertial pos="0.014563 0.02 -0.013765" quat="0 0.73395 0 0.679204" mass="0.136733"
                  diaginertia="0.00031963 0.000298 4.73705e-05" />
                <joint name="leg_r5_joint" pos="0 0 0" axis="0 1 0" range="-0.9 0.2" />
                <geom type="mesh" contype="0" conaffinity="0" group="1" density="0"
                  rgba="0.752941 0.752941 0.752941 1" mesh="leg_r5" />
                <geom type="mesh" rgba="0.752941 0.752941 0.752941 1" mesh="leg_r5" />
              </body>
            </body>
          </body>
        </body>
      </body>
      <body name="r_shoulder_pitch" pos="0.0015211 -0.1421 0.19236">
        <inertial pos="0.0392093 -0.00536176 -0.134669"
          quat="0.986935 0.0808683 -0.12232 -0.0667632" mass="1.31737"
          diaginertia="0.0215362 0.021178 0.00137825" />
        <joint name="r_shoulder_pitch_joint" pos="0 0 0" axis="0 1 0" range="-0.5 0.5" />
        <geom type="mesh" contype="0" conaffinity="0" group="1" density="0"
          rgba="0.752941 0.752941 0.752941 1" mesh="r_shoulder_pitch" />
        <geom type="mesh" rgba="0.752941 0.752941 0.752941 1" mesh="r_shoulder_pitch" />
        <geom pos="0.0294988 -0.04895 0.00026426" quat="0.999986 0 0 -0.00535214" type="mesh"
          contype="0" conaffinity="0" group="1" density="0" rgba="0.752941 0.752941 0.752941 1"
          mesh="r_shoulder_roll" />
        <geom pos="0.0294988 -0.04895 0.00026426" quat="0.999986 0 0 -0.00535214" type="mesh"
          rgba="0.752941 0.752941 0.752941 1" mesh="r_shoulder_roll" />
        <geom pos="-0.00376034 -0.04895 -0.082587" quat="0.999986 0 0 -0.00535214" type="mesh"
          contype="0" conaffinity="0" group="1" density="0" rgba="0.752941 0.752941 0.752941 1"
          mesh="r_shoulder_yaw" />
        <geom pos="-0.00376034 -0.04895 -0.082587" quat="0.999986 0 0 -0.00535214" type="mesh"
          rgba="0.752941 0.752941 0.752941 1" mesh="r_shoulder_yaw" />
        <geom pos="-0.00283789 -0.064475 -0.185558" quat="0.999986 0 0 -0.00535214" type="mesh"
          contype="0" conaffinity="0" group="1" density="0" rgba="0.752941 0.752941 0.752941 1"
          mesh="r_arm_pitch" />
        <geom pos="-0.00283789 -0.064475 -0.185558" quat="0.999986 0 0 -0.00535214" type="mesh"
          rgba="0.752941 0.752941 0.752941 1" mesh="r_arm_pitch" />
      </body>
      <body name="l_shoulder_pitch" pos="-0.0015211 0.1421 0.19236">
        <inertial pos="-0.0395794 -0.00642149 -0.140608"
          quat="0.659874 -0.0813695 0.149702 0.731803" mass="1.31769"
          diaginertia="0.0212062 0.0207577 0.00144543" />
        <joint name="l_shoulder_pitch_joint" pos="0 0 0" axis="0 1 0" range="-0.5 0.5" />
        <geom type="mesh" contype="0" conaffinity="0" group="1" density="0"
          rgba="0.752941 0.752941 0.752941 1" mesh="l_shoulder_pitch" />
        <geom type="mesh" rgba="0.752941 0.752941 0.752941 1" mesh="l_shoulder_pitch" />
        <geom pos="0.0289619 0.0492628 -0.00085627" quat="1 0 0 0" type="mesh" contype="0"
          conaffinity="0" group="1" density="0" rgba="0.752941 0.752941 0.752941 1"
          mesh="l_shoulder_roll" />
        <geom pos="0.0289619 0.0492628 -0.00085627" quat="1 0 0 0" type="mesh"
          rgba="0.752941 0.752941 0.752941 1" mesh="l_shoulder_roll" />
        <geom pos="-0.00741778 0.0488734 -0.0823846" quat="1 0 0 0" type="mesh" contype="0"
          conaffinity="0" group="1" density="0" rgba="0.752941 0.752941 0.752941 1"
          mesh="l_shoulder_yaw" />
        <geom pos="-0.00741778 0.0488734 -0.0823846" quat="1 0 0 0" type="mesh"
          rgba="0.752941 0.752941 0.752941 1" mesh="l_shoulder_yaw" />
        <geom pos="-0.0105727 0.0643655 -0.185316" type="mesh" contype="0" conaffinity="0" group="1"
          density="0" rgba="0.752941 0.752941 0.752941 1" mesh="l_arm_pitch" />
        <geom pos="-0.0105727 0.0643655 -0.185316" type="mesh" rgba="0.752941 0.752941 0.752941 1"
          mesh="l_arm_pitch" />
      </body>
    </body>
  </worldbody>

  <!-- actuator -->
  <actuator>
    <motor name="leg_l1_joint" joint="leg_l1_joint" gear="1" ctrllimited="true" ctrlrange="-60 60" />
    <motor name="leg_l2_joint" joint="leg_l2_joint" gear="1" ctrllimited="true" ctrlrange="-10 10" />
    <motor name="leg_l3_joint" joint="leg_l3_joint" gear="1" ctrllimited="true" ctrlrange="-20 20" />
    <motor name="leg_l4_joint" joint="leg_l4_joint" gear="1" ctrllimited="true" ctrlrange="-60 60" />
    <motor name="leg_l5_joint" joint="leg_l5_joint" gear="1" ctrllimited="true" ctrlrange="-10 10" />

    <motor name="leg_r1_joint" joint="leg_r1_joint" gear="1" ctrllimited="true" ctrlrange="-60 60" />
    <motor name="leg_r2_joint" joint="leg_r2_joint" gear="1" ctrllimited="true" ctrlrange="-10 10" />
    <motor name="leg_r3_joint" joint="leg_r3_joint" gear="1" ctrllimited="true" ctrlrange="-20 20" />
    <motor name="leg_r4_joint" joint="leg_r4_joint" gear="1" ctrllimited="true" ctrlrange="-60 60" />
    <motor name="leg_r5_joint" joint="leg_r5_joint" gear="1" ctrllimited="true" ctrlrange="-10 10" />

    <motor name="r_shoulder_pitch_joint" joint="r_shoulder_pitch_joint" gear="1" ctrllimited="true"
      ctrlrange="-10 10" />
    <motor name="l_shoulder_pitch_joint" joint="l_shoulder_pitch_joint" gear="1" ctrllimited="true"
      ctrlrange="-10 10" />
  </actuator>
  <!--</sensor> -->
  <sensor>
    <framequat name='orientation' objtype='site' objname='imu' />
    <framepos name='position' objtype='site' objname='imu' />
    <gyro name='angular-velocity' site='imu' cutoff='34.9' />
    <velocimeter name='linear-velocity' site='imu' cutoff='30' />
    <accelerometer name='linear-acceleration' site='imu' cutoff='157' />
    <magnetometer name='magnetometer' site='imu' />
  </sensor>
</mujoco>